Workbook
Name ________1736LAMA_Kota_Kabupaten: #REF!
Name ________1736LAMA_Kota_Kabupaten: #REF!
Name ________1736LAMA_Kota_Kabupaten: #REF!
Name ________1736LAMA_Kota_Kabupaten: #REF!
Name ________1736LAMA_Kota_Kabupaten: #REF!
Name ________1736LAMA_Kota_Kabupaten: #REF!
Name ________1736LAMA_Kota_Kabupaten: #REF!
Name ________1736LAMA_Kota_Kabupaten: #REF!
Name ________1736LAMA_Kota_Kabupaten: #REF!
Name ________1736LAMA_Kota_Kabupaten: #REF!
Name ________1736LAMA_Kota_Kabupaten: #REF!
Name ________1736LAMA_Kota_Kabupaten: #REF!
Name ________1736LAMA_Kota_Kabupaten: #REF!
Name ________1736LAMA_Kota_Kabupaten: #REF!
Name ________1736LAMA_Kota_Kabupaten: #REF!
Name ________1736LAMA_Kota_Kabupaten: #REF!
Name ________1736LAMA_Kota_Kabupaten: #REF!
Name ________1736LAMA_Kota_Kabupaten: #REF!
Name _______1736LAMA_Kota_Kabupaten: #REF!
Name _______1736LAMA_Kota_Kabupaten: #REF!
Name _______1736LAMA_Kota_Kabupaten: #REF!
Name _______1736LAMA_Kota_Kabupaten: #REF!
Name _______1736LAMA_Kota_Kabupaten: #REF!
Name _______1736LAMA_Kota_Kabupaten: #REF!
Name _______1736LAMA_Kota_Kabupaten: #REF!
Name _______1736LAMA_Kota_Kabupaten: #REF!
Name _______1736LAMA_Kota_Kabupaten: #REF!
Name _______1736LAMA_Kota_Kabupaten: #REF!
Name _______1736LAMA_Kota_Kabupaten: #REF!
Name _______1736LAMA_Kota_Kabupaten: #REF!
Name _______1736LAMA_Kota_Kabupaten: #REF!
Name _______1736LAMA_Kota_Kabupaten: #REF!
Name _______1736LAMA_Kota_Kabupaten: #REF!
Name _______1736LAMA_Kota_Kabupaten: #REF!
Name _______1736LAMA_Kota_Kabupaten: #REF!
Name _______1736LAMA_Kota_Kabupaten: #REF!
Name ______1736LAMA_Kota_Kabupaten: #REF!
Name ______1736LAMA_Kota_Kabupaten: #REF!
Name ______1736LAMA_Kota_Kabupaten: #REF!
Name ______1736LAMA_Kota_Kabupaten: #REF!
Name ______1736LAMA_Kota_Kabupaten: #REF!
Name ______1736LAMA_Kota_Kabupaten: #REF!
Name ______1736LAMA_Kota_Kabupaten: #REF!
Name ______1736LAMA_Kota_Kabupaten: #REF!
Name ______1736LAMA_Kota_Kabupaten: #REF!
Name ______1736LAMA_Kota_Kabupaten: #REF!
Name ______1736LAMA_Kota_Kabupaten: #REF!
Name ______1736LAMA_Kota_Kabupaten: #REF!
Name ______1736LAMA_Kota_Kabupaten: #REF!
Name ______1736LAMA_Kota_Kabupaten: #REF!
Name ______1736LAMA_Kota_Kabupaten: #REF!
Name ______1736LAMA_Kota_Kabupaten: #REF!
Name ______1736LAMA_Kota_Kabupaten: #REF!
Name ______1736LAMA_Kota_Kabupaten: #REF!
Name _____1736LAMA_Kota_Kabupaten: #REF!
Name _____1736LAMA_Kota_Kabupaten: #REF!
Name _____1736LAMA_Kota_Kabupaten: #REF!
Name _____1736LAMA_Kota_Kabupaten: #REF!
Name _____1736LAMA_Kota_Kabupaten: #REF!
Name _____1736LAMA_Kota_Kabupaten: #REF!

Sheet M1Bj_MjB1
A1: Kelurahan | C1: UMKM & Industri Lokal | D1: Akses ke Modal & Lembaga Keuangan | E1: Izin/Regulasi Mendukung | F1: Pasar & Distribusi | G1: Total | H1: Linguistik | I1: miu | J1: v
A2: MADIUN | N2: miu | O2: v | P2: SUM | S2: miu | T2: v | U2: SUM | X2: miu | Y2: v | Z2: SUM | AC2: miu | AD2: v | AE2: SUM | AH2: miu | AI2: v | AJ2: SUM | AM2: miu | AN2: v | AO2: SUM
A3: Kejuron | B3: M1 | C3: 2 | D3: 2 | E3: 2 | F3: 3 | G3: 9 | H3: CP | I3: =IF(H3="SP",0.9,IF(H3="P",0.7,IF(H3="CP",0.5,IF(H3="KP",0.3,0.1)))) -> 0.5 | J3: =IF(H3="SP",0.1,IF(H3="P",0.2,IF(H3="CP",0.3,IF(H3="KP",0.5,0.8)))) -> 0.3 | M3: M1B1 | N3: =ABS($I$3-I11) -> 0.2 | O3: =ABS($J$3-J11) -> 0.2 | P3: =N3+O3 -> 0.4 | R3: M2B1 | S3: =ABS($I$4-I11) -> 0 | T3: =ABS($J$4-J11) -> 0 | U3: =S3+T3 -> 0 | W3: M3B1 | X3: =ABS($I$5-I11) -> 0.4 | Y3: =ABS($J$5-J11) -> 0.3 | Z3: =X3+Y3 -> 0.7 | AB3: M4B1 | AC3: =ABS($I$6-I11) -> 0.2 | AD3: =ABS($J$6-J11) -> 0.3 | AE3: =AC3+AD3 -> 0.5 | AG3: M5B1 | AH3: =ABS($I$7-I11) -> 0.2 | AI3: =ABS($J$7-J11) -> 0.2 | AJ3: =AH3+AI3 -> 0.4 | AL3: M6B1 | AM3: =ABS($I$8-I11) -> 0.4 | AN3: =ABS($J$8-J11) -> 0.3 | AO3: =AM3+AN3 -> 0.7
A4: Kelun | B4: M2 | C4: 4 | D4: 3 | E4: 4 | F4: 4 | G4: 15 | H4: KP | I4: =IF(H4="SP",0.9,IF(H4="P",0.7,IF(H4="CP",0.5,IF(H4="KP",0.3,0.1)))) -> 0.3 | J4: =IF(H4="SP",0.1,IF(H4="P",0.2,IF(H4="CP",0.3,IF(H4="KP",0.5,0.8)))) -> 0.5 | M4: M1B2 | N4: =ABS($I$3-I12) -> 0 | O4: =ABS($J$3-J12) -> 0 | P4: =N4+O4 -> 0 | R4: M2B2 | S4: =ABS($I$4-I12) -> 0.2 | T4: =ABS($J$4-J12) -> 0.2 | U4: =S4+T4 -> 0.4 | W4: M3B2 | X4: =ABS($I$5-I12) -> 0.2 | Y4: =ABS($J$5-J12) -> 0.1 | Z4: =X4+Y4 -> 0.3 | AB4: M4B2 | AC4: =ABS($I$6-I12) -> 0.4 | AD4: =ABS($J$6-J12) -> 0.5 | AE4: =AC4+AD4 -> 0.9 | AG4: M5B2 | AH4: =ABS($I$7-I12) -> 0 | AI4: =ABS($J$7-J12) -> 0 | AJ4: =AH4+AI4 -> 0 | AL4: M6B2 | AM4: =ABS($I$8-I12) -> 0.2 | AN4: =ABS($J$8-J12) -> 0.1 | AO4: =AM4+AN4 -> 0.3
A5: Nambangan kidul | B5: M3 | C5: 1 | D5: 2 | E5: 2 | F5: 2 | G5: 8 | H5: P | I5: =IF(H5="SP",0.9,IF(H5="P",0.7,IF(H5="CP",0.5,IF(H5="KP",0.3,0.1)))) -> 0.7 | J5: =IF(H5="SP",0.1,IF(H5="P",0.2,IF(H5="CP",0.3,IF(H5="KP",0.5,0.8)))) -> 0.2 | M5: M1B3 | N5: =ABS($I$3-I13) -> 0 | O5: =ABS($J$3-J13) -> 0 | P5: =N5+O5 -> 0 | R5: M2B3 | S5: =ABS($I$4-I13) -> 0.2 | T5: =ABS($J$4-J13) -> 0.2 | U5: =S5+T5 -> 0.4 | W5: M3B3 | X5: =ABS($I$5-I13) -> 0.2 | Y5: =ABS($J$5-J13) -> 0.1 | Z5: =X5+Y5 -> 0.3 | AB5: M4B3 | AC5: =ABS($I$6-I13) -> 0.4 | AD5: =ABS($J$6-J13) -> 0.5 | AE5: =AC5+AD5 -> 0.9 | AG5: M5B3 | AH5: =ABS($I$7-I13) -> 0 | AI5: =ABS($J$7-J13) -> 0 | AJ5: =AH5+AI5 -> 0 | AL5: M6B3 | AM5: =ABS($I$8-I13) -> 0.2 | AN5: =ABS($J$8-J13) -> 0.1 | AO5: =AM5+AN5 -> 0.3
A6: Nambangan Lor | B6: M4 | C6: 5 | D6: 5 | E6: 5 | F6: 4 | G6: 19 | H6: TP | I6: =IF(H6="SP",0.9,IF(H6="P",0.7,IF(H6="CP",0.5,IF(H6="KP",0.3,0.1)))) -> 0.1 | J6: =IF(H6="SP",0.1,IF(H6="P",0.2,IF(H6="CP",0.3,IF(H6="KP",0.5,0.8)))) -> 0.8 | M6: M1B4 | N6: =ABS($I$3-I14) -> 0 | O6: =ABS($J$3-J14) -> 0 | P6: =N6+O6 -> 0 | R6: M2B4 | S6: =ABS($I$4-I14) -> 0.2 | T6: =ABS($J$4-J14) -> 0.2 | U6: =S6+T6 -> 0.4 | W6: M3B4 | X6: =ABS($I$5-I14) -> 0.2 | Y6: =ABS($J$5-J14) -> 0.1 | Z6: =X6+Y6 -> 0.3 | AB6: M4B4 | AC6: =ABS($I$6-I14) -> 0.4 | AD6: =ABS($J$6-J14) -> 0.5 | AE6: =AC6+AD6 -> 0.9 | AG6: M5B4 | AH6: =ABS($I$7-I14) -> 0 | AI6: =ABS($J$7-J14) -> 0 | AJ6: =AH6+AI6 -> 0 | AL6: M6B4 | AM6: =ABS($I$8-I14) -> 0.2 | AN6: =ABS($J$8-J14) -> 0.1 | AO6: =AM6+AN6 -> 0.3
A7: Pandean | B7: M5 | C7: 3 | D7: 2 | E7: 3 | F7: 3 | G7: 11 | H7: CP | I7: =IF(H7="SP",0.9,IF(H7="P",0.7,IF(H7="CP",0.5,IF(H7="KP",0.3,0.1)))) -> 0.5 | J7: =IF(H7="SP",0.1,IF(H7="P",0.2,IF(H7="CP",0.3,IF(H7="KP",0.5,0.8)))) -> 0.3 | M7: M1B5 | N7: =ABS($I$3-I15) -> 0.2 | O7: =ABS($J$3-J15) -> 0.1 | P7: =N7+O7 -> 0.3 | R7: M2B5 | S7: =ABS($I$4-I15) -> 0.4 | T7: =ABS($J$4-J15) -> 0.3 | U7: =S7+T7 -> 0.7 | W7: M3B5 | X7: =ABS($I$5-I15) -> 0 | Y7: =ABS($J$5-J15) -> 0 | Z7: =X7+Y7 -> 0 | AB7: M4B5 | AC7: =ABS($I$6-I15) -> 0.6 | AD7: =ABS($J$6-J15) -> 0.6 | AE7: =AC7+AD7 -> 1.2 | AG7: M5B5 | AH7: =ABS($I$7-I15) -> 0.2 | AI7: =ABS($J$7-J15) -> 0.1 | AJ7: =AH7+AI7 -> 0.3 | AL7: M6B5 | AM7: =ABS($I$8-I15) -> 0 | AN7: =ABS($J$8-J15) -> 0 | AO7: =AM7+AN7 -> 0
A8: Tawang | B8: M6 | C8: 2 | D8: 2 | E8: 2 | F8: 2 | G8: 8 | H8: P | I8: =IF(H8="SP",0.9,IF(H8="P",0.7,IF(H8="CP",0.5,IF(H8="KP",0.3,0.1)))) -> 0.7 | J8: =IF(H8="SP",0.1,IF(H8="P",0.2,IF(H8="CP",0.3,IF(H8="KP",0.5,0.8)))) -> 0.2 | M8: M1B6 | N8: =ABS($I$3-I16) -> 0.2 | O8: =ABS($J$3-J16) -> 0.1 | P8: =N8+O8 -> 0.3 | R8: M2B6 | S8: =ABS($I$4-I16) -> 0.4 | T8: =ABS($J$4-J16) -> 0.3 | U8: =S8+T8 -> 0.7 | W8: M3B6 | X8: =ABS($I$5-I16) -> 0 | Y8: =ABS($J$5-J16) -> 0 | Z8: =X8+Y8 -> 0 | AB8: M4B6 | AC8: =ABS($I$6-I16) -> 0.6 | AD8: =ABS($J$6-J16) -> 0.6 | AE8: =AC8+AD8 -> 1.2 | AG8: M5B6 | AH8: =ABS($I$7-I16) -> 0.2 | AI8: =ABS($J$7-J16) -> 0.1 | AJ8: =AH8+AI8 -> 0.3 | AL8: M6B6 | AM8: =ABS($I$8-I16) -> 0 | AN8: =ABS($J$8-J16) -> 0 | AO8: =AM8+AN8 -> 0
A10: BOJONEGORO | N10: miu | O10: v | P10: SUM | S10: miu | T10: v | U10: SUM | X10: miu | Y10: v | Z10: SUM | AC10: miu | AD10: v | AE10: SUM | AH10: miu | AI10: v | AJ10: SUM | AM10: miu | AN10: v | AO10: SUM
A11: Jetak | B11: B1 | C11: 4 | D11: 3 | E11: 3 | F11: 3 | G11: 13 | H11: KP | I11: =IF(H11="SP",0.9,IF(H11="P",0.7,IF(H11="CP",0.5,IF(H11="KP",0.3,0.1)))) -> 0.3 | J11: =IF(H11="SP",0.1,IF(H11="P",0.2,IF(H11="CP",0.3,IF(H11="KP",0.5,0.8)))) -> 0.5 | M11: M1B1 | N11: =ABS(I3-$I$11) -> 0.2 | O11: =ABS(J3-$J$11) -> 0.2 | P11: =N11+O11 -> 0.4 | R11: M1B2 | S11: =ABS(I3-$I$12) -> 0 | T11: =ABS(J3-$J$12) -> 0 | U11: =S11+T11 -> 0 | W11: M1B3 | X11: =ABS(I3-$I$13) -> 0 | Y11: =ABS(J3-$J$13) -> 0 | Z11: =X11+Y11 -> 0 | AB11: M1B4 | AC11: =ABS(I3-$I$14) -> 0 | AD11: =ABS(J3-$J$14) -> 0 | AE11: =AC11+AD11 -> 0 | AG11: M1B5 | AH11: =ABS(I3-$I$15) -> 0.2 | AI11: =ABS(J3-$J$15) -> 0.1 | AJ11: =AH11+AI11 -> 0.3 | AL11: M1B6 | AM11: =ABS(I3-$I$16) -> 0.2 | AN11: =ABS(J3-$J$16) -> 0.1 | AO11: =AM11+AN11 -> 0.3
A12: Kadipaten | B12: B2 | C12: 3 | D12: 3 | E12: 3 | F12: 3 | G12: 12 | H12: CP | I12: =IF(H12="SP",0.9,IF(H12="P",0.7,IF(H12="CP",0.5,IF(H12="KP",0.3,0.1)))) -> 0.5 | J12: =IF(H12="SP",0.1,IF(H12="P",0.2,IF(H12="CP",0.3,IF(H12="KP",0.5,0.8)))) -> 0.3 | M12: M2B1 | N12: =ABS(I4-$I$11) -> 0 | O12: =ABS(J4-$J$11) -> 0 | P12: =N12+O12 -> 0 | R12: M2B2 | S12: =ABS(I4-$I$12) -> 0.2 | T12: =ABS(J4-$J$12) -> 0.2 | U12: =S12+T12 -> 0.4 | W12: M2B3 | X12: =ABS(I4-$I$13) -> 0.2 | Y12: =ABS(J4-$J$13) -> 0.2 | Z12: =X12+Y12 -> 0.4 | AB12: M2B4 | AC12: =ABS(I4-$I$14) -> 0.2 | AD12: =ABS(J4-$J$14) -> 0.2 | AE12: =AC12+AD12 -> 0.4 | AG12: M2B5 | AH12: =ABS(I4-$I$15) -> 0.4 | AI12: =ABS(J4-$J$15) -> 0.3 | AJ12: =AH12+AI12 -> 0.7 | AL12: M2B6 | AM12: =ABS(I4-$I$16) -> 0.4 | AN12: =ABS(J4-$J$16) -> 0.3 | AO12: =AM12+AN12 -> 0.7
A13: Karang Pacar | B13: B3 | C13: 3 | D13: 2 | E13: 2 | F13: 2 | G13: 9 | H13: CP | I13: =IF(H13="SP",0.9,IF(H13="P",0.7,IF(H13="CP",0.5,IF(H13="KP",0.3,0.1)))) -> 0.5 | J13: =IF(H13="SP",0.1,IF(H13="P",0.2,IF(H13="CP",0.3,IF(H13="KP",0.5,0.8)))) -> 0.3 | M13: M3B1 | N13: =ABS(I5-$I$11) -> 0.4 | O13: =ABS(J5-$J$11) -> 0.3 | P13: =N13+O13 -> 0.7 | R13: M3B2 | S13: =ABS(I5-$I$12) -> 0.2 | T13: =ABS(J5-$J$12) -> 0.1 | U13: =S13+T13 -> 0.3 | W13: M3B3 | X13: =ABS(I5-$I$13) -> 0.2 | Y13: =ABS(J5-$J$13) -> 0.1 | Z13: =X13+Y13 -> 0.3 | AB13: M3B4 | AC13: =ABS(I5-$I$14) -> 0.2 | AD13: =ABS(J5-$J$14) -> 0.1 | AE13: =AC13+AD13 -> 0.3 | AG13: M3B5 | AH13: =ABS(I5-$I$15) -> 0 | AI13: =ABS(J5-$J$15) -> 0 | AJ13: =AH13+AI13 -> 0 | AL13: M3B6 | AM13: =ABS(I5-$I$16) -> 0 | AN13: =ABS(J5-$J$16) -> 0 | AO13: =AM13+AN13 -> 0
A14: Klangon | B14: B4 | C14: 3 | D14: 2 | E14: 2 | F14: 2 | G14: 9 | H14: CP | I14: =IF(H14="SP",0.9,IF(H14="P",0.7,IF(H14="CP",0.5,IF(H14="KP",0.3,0.1)))) -> 0.5 | J14: =IF(H14="SP",0.1,IF(H14="P",0.2,IF(H14="CP",0.3,IF(H14="KP",0.5,0.8)))) -> 0.3 | M14: M4B1 | N14: =ABS(I6-$I$11) -> 0.2 | O14: =ABS(J6-$J$11) -> 0.3 | P14: =N14+O14 -> 0.5 | R14: M4B2 | S14: =ABS(I6-$I$12) -> 0.4 | T14: =ABS(J6-$J$12) -> 0.5 | U14: =S14+T14 -> 0.9 | W14: M4B3 | X14: =ABS(I6-$I$13) -> 0.4 | Y14: =ABS(J6-$J$13) -> 0.5 | Z14: =X14+Y14 -> 0.9 | AB14: M4B4 | AC14: =ABS(I6-$I$14) -> 0.4 | AD14: =ABS(J6-$J$14) -> 0.5 | AE14: =AC14+AD14 -> 0.9 | AG14: M4B5 | AH14: =ABS(I6-$I$15) -> 0.6 | AI14: =ABS(J6-$J$15) -> 0.6 | AJ14: =AH14+AI14 -> 1.2 | AL14: M4B6 | AM14: =ABS(I6-$I$16) -> 0.6 | AN14: =ABS(J6-$J$16) -> 0.6 | AO14: =AM14+AN14 -> 1.2
A15: Ledok Kulon | B15: B5 | C15: 2 | D15: 2 | E15: 2 | F15: 2 | G15: 8 | H15: P | I15: =IF(H15="SP",0.9,IF(H15="P",0.7,IF(H15="CP",0.5,IF(H15="KP",0.3,0.1)))) -> 0.7 | J15: =IF(H15="SP",0.1,IF(H15="P",0.2,IF(H15="CP",0.3,IF(H15="KP",0.5,0.8)))) -> 0.2 | M15: M5B1 | N15: =ABS(I7-$I$11) -> 0.2 | O15: =ABS(J7-$J$11) -> 0.2 | P15: =N15+O15 -> 0.4 | R15: M5B2 | S15: =ABS(I7-$I$12) -> 0 | T15: =ABS(J7-$J$12) -> 0 | U15: =S15+T15 -> 0 | W15: M5B3 | X15: =ABS(I7-$I$13) -> 0 | Y15: =ABS(J7-$J$13) -> 0 | Z15: =X15+Y15 -> 0 | AB15: M5B4 | AC15: =ABS(I7-$I$14) -> 0 | AD15: =ABS(J7-$J$14) -> 0 | AE15: =AC15+AD15 -> 0 | AG15: M5B5 | AH15: =ABS(I7-$I$15) -> 0.2 | AI15: =ABS(J7-$J$15) -> 0.1 | AJ15: =AH15+AI15 -> 0.3 | AL15: M5B6 | AM15: =ABS(I7-$I$16) -> 0.2 | AN15: =ABS(J7-$J$16) -> 0.1 | AO15: =AM15+AN15 -> 0.3
A16: Ledok Wetan | B16: B6 | C16: 2 | D16: 2 | E16: 2 | F16: 2 | G16: 8 | H16: P | I16: =IF(H16="SP",0.9,IF(H16="P",0.7,IF(H16="CP",0.5,IF(H16="KP",0.3,0.1)))) -> 0.7 | J16: =IF(H16="SP",0.1,IF(H16="P",0.2,IF(H16="CP",0.3,IF(H16="KP",0.5,0.8)))) -> 0.2 | M16: M6B1 | N16: =ABS(I8-$I$11) -> 0.4 | O16: =ABS(J8-$J$11) -> 0.3 | P16: =N16+O16 -> 0.7 | R16: M6B2 | S16: =ABS(I8-$I$12) -> 0.2 | T16: =ABS(J8-$J$12) -> 0.1 | U16: =S16+T16 -> 0.3 | W16: M6B3 | X16: =ABS(I8-$I$13) -> 0.2 | Y16: =ABS(J8-$J$13) -> 0.1 | Z16: =X16+Y16 -> 0.3 | AB16: M6B4 | AC16: =ABS(I8-$I$14) -> 0.2 | AD16: =ABS(J8-$J$14) -> 0.1 | AE16: =AC16+AD16 -> 0.3 | AG16: M6B5 | AH16: =ABS(I8-$I$15) -> 0 | AI16: =ABS(J8-$J$15) -> 0 | AJ16: =AH16+AI16 -> 0 | AL16: M6B6 | AM16: =ABS(I8-$I$16) -> 0 | AN16: =ABS(J8-$J$16) -> 0 | AO16: =AM16+AN16 -> 0
A17: MAGETAN
A18: Baron | B18: MG1 | C18: 4 | D18: 3 | E18: 3 | F18: 3 | G18: 13 | H18: KP | I18: =IF(H18="SP",0.9,IF(H18="P",0.7,IF(H18="CP",0.5,IF(H18="KP",0.3,0.1)))) -> 0.3 | J18: =IF(H18="SP",0.1,IF(H18="P",0.2,IF(H18="CP",0.3,IF(H18="KP",0.5,0.8)))) -> 0.5
A19: Bulukerto | B19: MG2 | C19: 3 | D19: 3 | E19: 3 | F19: 3 | G19: 12 | H19: CP | I19: =IF(H19="SP",0.9,IF(H19="P",0.7,IF(H19="CP",0.5,IF(H19="KP",0.3,0.1)))) -> 0.5 | J19: =IF(H19="SP",0.1,IF(H19="P",0.2,IF(H19="CP",0.3,IF(H19="KP",0.5,0.8)))) -> 0.3 | M19: MIN (M1, BJ) | N19: =MIN(P3:P8) -> 0 | P19: MIN(MJ,B1) | Q19: =MIN(P11:P16) -> 0
A20: Candi Rejo | B20: MG3 | C20: 3 | D20: 2 | E20: 2 | F20: 2 | G20: 9 | H20: CP | I20: =IF(H20="SP",0.9,IF(H20="P",0.7,IF(H20="CP",0.5,IF(H20="KP",0.3,0.1)))) -> 0.5 | J20: =IF(H20="SP",0.1,IF(H20="P",0.2,IF(H20="CP",0.3,IF(H20="KP",0.5,0.8)))) -> 0.3 | M20: MIN (M2, BJ) | N20: =MIN(U3:U8) -> 0 | P20: MIN (MJ, B2) | Q20: =MIN(U11:U16) -> 0
A21: Magetan | B21: MG4 | C21: 4 | D21: 3 | E21: 3 | F21: 4 | G21: 14 | H21: KP | I21: =IF(H21="SP",0.9,IF(H21="P",0.7,IF(H21="CP",0.5,IF(H21="KP",0.3,0.1)))) -> 0.3 | J21: =IF(H21="SP",0.1,IF(H21="P",0.2,IF(H21="CP",0.3,IF(H21="KP",0.5,0.8)))) -> 0.5 | M21: MIN (M3, BJ) | N21: =MIN(Z3:Z8) -> 0 | P21: MIN (MJ, B3) | Q21: =MIN(Z11:Z16) -> 0
A22: Ringinagung | B22: MG5 | C22: 2 | D22: 2 | E22: 2 | F22: 2 | G22: 8 | H22: P | I22: =IF(H22="SP",0.9,IF(H22="P",0.7,IF(H22="CP",0.5,IF(H22="KP",0.3,0.1)))) -> 0.7 | J22: =IF(H22="SP",0.1,IF(H22="P",0.2,IF(H22="CP",0.3,IF(H22="KP",0.5,0.8)))) -> 0.2 | M22: MIN (M4, BJ) | N22: =MIN(AE3:AE8) -> 0.5 | P22: MIN (MJ, B4) | Q22: =MIN(AE11:AE16) -> 0
A23: Selosari | B23: MG6 | C23: 2 | D23: 2 | E23: 2 | F23: 2 | G23: 8 | H23: P | I23: =IF(H23="SP",0.9,IF(H23="P",0.7,IF(H23="CP",0.5,IF(H23="KP",0.3,0.1)))) -> 0.7 | J23: =IF(H23="SP",0.1,IF(H23="P",0.2,IF(H23="CP",0.3,IF(H23="KP",0.5,0.8)))) -> 0.2 | M23: MIN (M5, BJ) | N23: =MIN(AJ3:AJ8) -> 0 | P23: MIN (MJ, B5) | Q23: =MIN(AJ11:AJ16) -> 0
M24: MIN (M6, BJ) | N24: =MIN(AO3:AO8) -> 0 | P24: MIN (MJ, B6) | Q24: =MIN(AO11:AO16) -> 0
M26: TOTAL MIN | N26: =SUM(N19:N24) -> 0.5 | P26: TOTAL MIN | Q26: =SUM(Q19:Q24) -> 0 | S26: R_MB | T26: =(1/(4.6))*(N26+Q26) -> 0.10869565
M29: R_MB | N29: =T26 -> 0.10869565
M30: R_mb | N30: ='mjb1'!H152 -> 0.10438596
M31: D_MB | N31: =(1/2) *(N29+N30) -> 0.10654081
M32: S_MB | N32: =1-N31 -> 0.89345919

Sheet mjb1
A1: M1B1 | B1: miu | C1: v | E1: M2B1 | F1: miu | G1: v | I1: M3B1 | J1: miu | K1: v | M1: M4B1 | N1: miu | O1: v | Q1: M5B1 | R1: miu | S1: v | U1: M6B1 | V1: miu | W1: v
A2: x1 | B2: =m1bj!B2 -> 0 | C2: =m1bj!C2 -> 0 | E2: x1 | F2: =m1bj!B25 -> 0 | G2: =m1bj!C25 -> 0 | I2: x1 | J2: =m1bj!B48 -> 0 | K2: =m1bj!C48 -> 0 | M2: x1 | N2: =m1bj!B72 -> 0.2 | O2: =m1bj!C72 -> 0.2 | Q2: x1 | R2: =m1bj!B95 -> 0.2 | S2: =m1bj!C95 -> 0.2 | U2: x1 | V2: =m1bj!B119 -> 0 | W2: =m1bj!C119 -> 0
A3: x2 | B3: =m1bj!B3 -> 0.4 | C3: =m1bj!C3 -> 0.4 | E3: x2 | F3: =m1bj!B26 -> 0.4 | G3: =m1bj!C26 -> 0.4 | I3: x2 | J3: =m1bj!B49 -> 0.4 | K3: =m1bj!C49 -> 0.4 | M3: x2 | N3: =m1bj!B73 -> 0.4 | O3: =m1bj!C73 -> 0.4 | Q3: x2 | R3: =m1bj!B96 -> 0.4 | S3: =m1bj!C96 -> 0.4 | U3: x2 | V3: =m1bj!B120 -> 0.4 | W3: =m1bj!C120 -> 0.4
A4: x3 | B4: =m1bj!B4 -> 0 | C4: =m1bj!C4 -> 0 | E4: x3 | F4: =m1bj!B27 -> 0 | G4: =m1bj!C27 -> 0 | I4: x3 | J4: =m1bj!B50 -> 0 | K4: =m1bj!C50 -> 0 | M4: x3 | N4: =m1bj!B74 -> 0 | O4: =m1bj!C74 -> 0 | Q4: x3 | R4: =m1bj!B97 -> 0 | S4: =m1bj!C97 -> 0 | U4: x3 | V4: =m1bj!B121 -> 0 | W4: =m1bj!C121 -> 0
A5: x4 | B5: =m1bj!B5 -> 0 | C5: =m1bj!C5 -> 0 | E5: x4 | F5: =m1bj!B28 -> 0 | G5: =m1bj!C28 -> 0 | I5: x4 | J5: =m1bj!B51 -> 0 | K5: =m1bj!C51 -> 0 | M5: x4 | N5: =m1bj!B75 -> 0 | O5: =m1bj!C75 -> 0 | Q5: x4 | R5: =m1bj!B98 -> 0 | S5: =m1bj!C98 -> 0 | U5: x4 | V5: =m1bj!B122 -> 0 | W5: =m1bj!C122 -> 0
A6: x5 | B6: =m1bj!B6 -> 0.2 | C6: =m1bj!C6 -> 0.2 | E6: x5 | F6: =m1bj!B29 -> 0.2 | G6: =m1bj!C29 -> 0.2 | I6: x5 | J6: =m1bj!B52 -> 0.2 | K6: =m1bj!C52 -> 0.2 | M6: x5 | N6: =m1bj!B76 -> 0.2 | O6: =m1bj!C76 -> 0.2 | Q6: x5 | R6: =m1bj!B99 -> 0.2 | S6: =m1bj!C99 -> 0.2 | U6: x5 | V6: =m1bj!B123 -> 0.2 | W6: =m1bj!C123 -> 0.2
A7: x6 | B7: =m1bj!B7 -> 0.2 | C7: =m1bj!C7 -> 0.2 | E7: x6 | F7: =m1bj!B30 -> 0.4 | G7: =m1bj!C30 -> 0.4 | I7: x6 | J7: =m1bj!B53 -> 0.4 | K7: =m1bj!C53 -> 0.4 | M7: x6 | N7: =m1bj!B77 -> 0.4 | O7: =m1bj!C77 -> 0.4 | Q7: x6 | R7: =m1bj!B100 -> 0 | S7: =m1bj!C100 -> 0 | U7: x6 | V7: =m1bj!B124 -> 0.4 | W7: =m1bj!C124 -> 0.4
A8: x7 | B8: =m1bj!B8 -> 0 | C8: =m1bj!C8 -> 0 | E8: x7 | F8: =m1bj!B31 -> 0 | G8: =m1bj!C31 -> 0 | I8: x7 | J8: =m1bj!B54 -> 0 | K8: =m1bj!C54 -> 0 | M8: x7 | N8: =m1bj!B78 -> 0 | O8: =m1bj!C78 -> 0 | Q8: x7 | R8: =m1bj!B101 -> 0 | S8: =m1bj!C101 -> 0 | U8: x7 | V8: =m1bj!B125 -> 0 | W8: =m1bj!C125 -> 0
A9: x8 | B9: =m1bj!B9 -> 0 | C9: =m1bj!C9 -> 0 | E9: x8 | F9: =m1bj!B32 -> 0 | G9: =m1bj!C32 -> 0 | I9: x8 | J9: =m1bj!B55 -> 0 | K9: =m1bj!C55 -> 0 | M9: x8 | N9: =m1bj!B79 -> 0 | O9: =m1bj!C79 -> 0 | Q9: x8 | R9: =m1bj!B102 -> 0 | S9: =m1bj!C102 -> 0 | U9: x8 | V9: =m1bj!B126 -> 0 | W9: =m1bj!C126 -> 0
A10: x9 | B10: =m1bj!B10 -> 0 | C10: =m1bj!C10 -> 0 | E10: x9 | F10: =m1bj!B33 -> 0.2 | G10: =m1bj!C33 -> 0.2 | I10: x9 | J10: =m1bj!B56 -> 0.2 | K10: =m1bj!C56 -> 0.2 | M10: x9 | N10: =m1bj!B80 -> 0.2 | O10: =m1bj!C80 -> 0.2 | Q10: x9 | R10: =m1bj!B103 -> 0.2 | S10: =m1bj!C103 -> 0.2 | U10: x9 | V10: =m1bj!B127 -> 0.2 | W10: =m1bj!C127 -> 0.2
A11: x10 | B11: =m1bj!B11 -> 0 | C11: =m1bj!C11 -> 0 | E11: x10 | F11: =m1bj!B34 -> 0 | G11: =m1bj!C34 -> 0 | I11: x10 | J11: =m1bj!B57 -> 0 | K11: =m1bj!C57 -> 0 | M11: x10 | N11: =m1bj!B81 -> 0 | O11: =m1bj!C81 -> 0 | Q11: x10 | R11: =m1bj!B104 -> 0 | S11: =m1bj!C104 -> 0 | U11: x10 | V11: =m1bj!B128 -> 0 | W11: =m1bj!C128 -> 0
A12: x11 | B12: =m1bj!B12 -> 0.2 | C12: =m1bj!C12 -> 0.2 | E12: x11 | F12: =m1bj!B35 -> 0.2 | G12: =m1bj!C35 -> 0.2 | I12: x11 | J12: =m1bj!B58 -> 0 | K12: =m1bj!C58 -> 0 | M12: x11 | N12: =m1bj!B82 -> 0.2 | O12: =m1bj!C82 -> 0.2 | Q12: x11 | R12: =m1bj!B105 -> 0.2 | S12: =m1bj!C105 -> 0.2 | U12: x11 | V12: =m1bj!B129 -> 0 | W12: =m1bj!C129 -> 0
A13: x12 | B13: =m1bj!B13 -> 0 | C13: =m1bj!C13 -> 0 | E13: x12 | F13: =m1bj!B36 -> 0 | G13: =m1bj!C36 -> 0 | I13: x12 | J13: =m1bj!B59 -> 0.2 | K13: =m1bj!C59 -> 0.2 | M13: x12 | N13: =m1bj!B83 -> 0 | O13: =m1bj!C83 -> 0 | Q13: x12 | R13: =m1bj!B106 -> 0 | S13: =m1bj!C106 -> 0 | U13: x12 | V13: =m1bj!B130 -> 0 | W13: =m1bj!C130 -> 0
... A20: x19 | B20: =m1bj!B20 -> 0.2 | C20: =m1bj!C20 -> 0.2 | E20: x19 | F20: =m1bj!B43 -> 0 | G20: =m1bj!C43 -> 0 | I20: x19 | J20: =m1bj!B66 -> 0.6 | K20: =m1bj!C66 -> 0.6 | M20: x19 | N20: =m1bj!B90 -> 0 | O20: =m1bj!C90 -> 0 | Q20: x19 | R20: =m1bj!B113 -> 0.6 | S20: =m1bj!C113 -> 0.6 | U20: x19 | V20: =m1bj!B137 -> 0 | W20: =m1bj!C137 -> 0
A21: SUM | B21: =SUM(B2:B20) -> 2.4 | C21: =SUM(C2:C20) -> 2.4 | F21: =SUM(F2:F20) -> 1.8 | G21: =SUM(G2:G20) -> 1.8 | J21: =SUM(J2:J20) -> 3.2 | K21: =SUM(K2:K20) -> 3.2 | N21: =SUM(N2:N20) -> 3 | O21: =SUM(O2:O20) -> 3 | R21: =SUM(R2:R20) -> 3.8 | S21: =SUM(S2:S20) -> 3.8 | V21: =SUM(V2:V20) -> 2.2 | W21: =SUM(W2:W20) -> 2.2
A22: 1/19*SUM | D22: =1/19*(B21+C21) -> 0.25263158 | H22: =1/19*(F21+G21) -> 0.18947368 | L22: =1/19*(J21+K21) -> 0.33684211 | P22: =1/19*(N21+O21) -> 0.31578947 | T22: =1/19*(R21+S21) -> 0.4 | X22: =1/19*(V21+W21) -> 0.23157895 | Y22: min | Z22: =MIN(B22:Y22) -> 0.18947368
A24: M1B2 | B24: miu | C24: v | E24: M2B2 | F24: miu | G24: v | I24: M3B2 | J24: miu | K24: v | M24: M4B2 | N24: miu | O24: v | Q24: M5B2 | R24: miu | S24: v | U24: M6B2 | V24: miu | W24: v
A25: x1 | B25: =m1bj!F2 -> 0 | C25: =m1bj!G2 -> 0 | E25: x1 | F25: =m1bj!F25 -> 0 | G25: =m1bj!G25 -> 0 | I25: x1 | J25: =m1bj!F48 -> 0 | K25: =m1bj!G48 -> 0 | M25: x1 | N25: =m1bj!F72 -> 0.2 | O25: =m1bj!G72 -> 0.2 | Q25: x1 | R25: =m1bj!F95 -> 0.2 | S25: =m1bj!G95 -> 0.2 | U25: x1 | V25: =m1bj!F119 -> 0 | W25: =m1bj!G119 -> 0
A26: x2 | B26: =m1bj!F3 -> 0.6 | C26: =m1bj!G3 -> 0.6 | E26: x2 | F26: =m1bj!F26 -> 0.6 | G26: =m1bj!G26 -> 0.6 | I26: x2 | J26: =m1bj!F49 -> 0.6 | K26: =m1bj!G49 -> 0.6 | M26: x2 | N26: =m1bj!F73 -> 0.6 | O26: =m1bj!G73 -> 0.6 | Q26: x2 | R26: =m1bj!F96 -> 0.6 | S26: =m1bj!G96 -> 0.6 | U26: x2 | V26: =m1bj!F120 -> 0.6 | W26: =m1bj!G120 -> 0.6
A27: x3 | B27: =m1bj!F4 -> 0 | C27: =m1bj!G4 -> 0 | E27: x3 | F27: =m1bj!F27 -> 0 | G27: =m1bj!G27 -> 0 | I27: x3 | J27: =m1bj!F50 -> 0 | K27: =m1bj!G50 -> 0 | M27: x3 | N27: =m1bj!F74 -> 0 | O27: =m1bj!G74 -> 0 | Q27: x3 | R27: =m1bj!F97 -> 0 | S27: =m1bj!G97 -> 0 | U27: x3 | V27: =m1bj!F121 -> 0 | W27: =m1bj!G121 -> 0
A28: x4 | B28: =m1bj!F5 -> 0 | C28: =m1bj!G5 -> 0 | E28: x4 | F28: =m1bj!F28 -> 0 | G28: =m1bj!G28 -> 0 | I28: x4 | J28: =m1bj!F51 -> 0 | K28: =m1bj!G51 -> 0 | M28: x4 | N28: =m1bj!F75 -> 0 | O28: =m1bj!G75 -> 0 | Q28: x4 | R28: =m1bj!F98 -> 0 | S28: =m1bj!G98 -> 0 | U28: x4 | V28: =m1bj!F122 -> 0 | W28: =m1bj!G122 -> 0
A29: x5 | B29: =m1bj!F6 -> 0 | C29: =m1bj!G6 -> 0 | E29: x5 | F29: =m1bj!F29 -> 0 | G29: =m1bj!G29 -> 0 | I29: x5 | J29: =m1bj!F52 -> 0 | K29: =m1bj!G52 -> 0 | M29: x5 | N29: =m1bj!F76 -> 0 | O29: =m1bj!G76 -> 0 | Q29: x5 | R29: =m1bj!F99 -> 0 | S29: =m1bj!G99 -> 0 | U29: x5 | V29: =m1bj!F123 -> 0 | W29: =m1bj!G123 -> 0
A30: x6 | B30: =m1bj!F7 -> 0.2 | C30: =m1bj!G7 -> 0.2 | E30: x6 | F30: =m1bj!F30 -> 0 | G30: =m1bj!G30 -> 0 | I30: x6 | J30: =m1bj!F53 -> 0 | K30: =m1bj!G53 -> 0 | M30: x6 | N30: =m1bj!F77 -> 0 | O30: =m1bj!G77 -> 0 | Q30: x6 | R30: =m1bj!F100 -> 0.4 | S30: =m1bj!G100 -> 0.4 | U30: x6 | V30: =m1bj!F124 -> 0 | W30: =m1bj!G124 -> 0
A31: x7 | B31: =m1bj!F8 -> 0 | C31: =m1bj!G8 -> 0 | E31: x7 | F31: =m1bj!F31 -> 0 | G31: =m1bj!G31 -> 0 | I31: x7 | J31: =m1bj!F54 -> 0 | K31: =m1bj!G54 -> 0 | M31: x7 | N31: =m1bj!F78 -> 0 | O31: =m1bj!G78 -> 0 | Q31: x7 | R31: =m1bj!F101 -> 0 | S31: =m1bj!G101 -> 0 | U31: x7 | V31: =m1bj!F125 -> 0 | W31: =m1bj!G125 -> 0
A32: x8 | B32: =m1bj!F9 -> 0.6 | C32: =m1bj!G9 -> 0.6 | E32: x8 | F32: =m1bj!F32 -> 0.6 | G32: =m1bj!G32 -> 0.6 | I32: x8 | J32: =m1bj!F55 -> 0.6 | K32: =m1bj!G55 -> 0.6 | M32: x8 | N32: =m1bj!F79 -> 0.6 | O32: =m1bj!G79 -> 0.6 | Q32: x8 | R32: =m1bj!F102 -> 0.6 | S32: =m1bj!G102 -> 0.6 | U32: x8 | V32: =m1bj!F126 -> 0.6 | W32: =m1bj!G126 -> 0.6
A33: x9 | B33: =m1bj!F10 -> 0.2 | C33: =m1bj!G10 -> 0.2 | E33: x9 | F33: =m1bj!F33 -> 0 | G33: =m1bj!G33 -> 0 | I33: x9 | J33: =m1bj!F56 -> 0 | K33: =m1bj!G56 -> 0 | M33: x9 | N33: =m1bj!F80 -> 0 | O33: =m1bj!G80 -> 0 | Q33: x9 | R33: =m1bj!F103 -> 0 | S33: =m1bj!G103 -> 0 | U33: x9 | V33: =m1bj!F127 -> 0 | W33: =m1bj!G127 -> 0
A34: x10 | B34: =m1bj!F11 -> 0 | C34: =m1bj!G11 -> 0 | E34: x10 | F34: =m1bj!F34 -> 0 | G34: =m1bj!G34 -> 0 | I34: x10 | J34: =m1bj!F57 -> 0 | K34: =m1bj!G57 -> 0 | M34: x10 | N34: =m1bj!F81 -> 0 | O34: =m1bj!G81 -> 0 | Q34: x10 | R34: =m1bj!F104 -> 0 | S34: =m1bj!G104 -> 0 | U34: x10 | V34: =m1bj!F128 -> 0 | W34: =m1bj!G128 -> 0
A35: x11 | B35: =m1bj!F12 -> 0.4 | C35: =m1bj!G12 -> 0.4 | E35: x11 | F35: =m1bj!F35 -> 0.4 | G35: =m1bj!G35 -> 0.4 | I35: x11 | J35: =m1bj!F58 -> 0.2 | K35: =m1bj!G58 -> 0.2 | M35: x11 | N35: =m1bj!F82 -> 0 | O35: =m1bj!G82 -> 0 | Q35: x11 | R35: =m1bj!F105 -> 0 | S35: =m1bj!G105 -> 0 | U35: x11 | V35: =m1bj!F129 -> 0.2 | W35: =m1bj!G129 -> 0.2
A36: x12 | B36: =m1bj!F13 -> 0 | C36: =m1bj!G13 -> 0 | E36: x12 | F36: =m1bj!F36 -> 0 | G36: =m1bj!G36 -> 0 | I36: x12 | J36: =m1bj!F59 -> 0.2 | K36: =m1bj!G59 -> 0.2 | M36: x12 | N36: =m1bj!F83 -> 0 | O36: =m1bj!G83 -> 0 | Q36: x12 | R36: =m1bj!F106 -> 0 | S36: =m1bj!G106 -> 0 | U36: x12 | V36: =m1bj!F130 -> 0 | W36: =m1bj!G130 -> 0
... A43: x19 | B43: =m1bj!F20 -> 0.2 | C43: =m1bj!G20 -> 0.2 | E43: x19 | F43: =m1bj!F43 -> 0 | G43: =m1bj!G43 -> 0 | I43: x19 | J43: =m1bj!F66 -> 0.6 | K43: =m1bj!G66 -> 0.6 | M43: x19 | N43: =m1bj!F90 -> 0 | O43: =m1bj!G90 -> 0 | Q43: x19 | R43: =m1bj!F113 -> 0.6 | S43: =m1bj!G113 -> 0.6 | U43: x19 | V43: =m1bj!F137 -> 0 | W43: =m1bj!G137 -> 0
B44: =SUM(B25:B43) -> 3.2 | C44: =SUM(C25:C43) -> 3.2 | F44: =SUM(F25:F43) -> 2.2 | G44: =SUM(G25:G43) -> 2.2 | J44: =SUM(J25:J43) -> 3.6 | K44: =SUM(K25:K43) -> 3.6 | N44: =SUM(N25:N43) -> 2.6 | O44: =SUM(O25:O43) -> 2.6 | R44: =SUM(R25:R43) -> 4.2 | S44: =SUM(S25:S43) -> 4.2 | V44: =SUM(V25:V43) -> 2.6 | W44: =SUM(W25:W43) -> 2.6
A45: 1/19*SUM | D45: =1/19*(B44+C44) -> 0.33684211 | H45: =1/19*(F44+G44) -> 0.23157895 | L45: =1/19*(J44+K44) -> 0.37894737 | P45: =1/19*(N44+O44) -> 0.27368421 | T45: =1/19*(R44+S44) -> 0.44210526 | X45: =1/19*(V44+W44) -> 0.27368421 | Y45: min | Z45: =MIN(B45:Y45) -> 0.23157895
A47: M1B3 | B47: miu | C47: v | E47: M2B3 | F47: miu | G47: v | I47: M3B3 | J47: miu | K47: v | M47: M4B3 | N47: miu | O47: v | Q47: M5B3 | R47: miu | S47: v | U47: M6B3 | V47: miu | W47: v
A48: x1 | B48: =m1bj!J2 -> 0.2 | C48: =m1bj!K2 -> 0.2 | E48: x1 | F48: =m1bj!J25 -> 0.2 | G48: =m1bj!K25 -> 0.2 | I48: x1 | J48: =m1bj!J48 -> 0.2 | K48: =m1bj!K48 -> 0.2 | M48: x1 | N48: =m1bj!J72 -> 0 | O48: =m1bj!K72 -> 0 | Q48: x1 | R48: =m1bj!J95 -> 0 | S48: =m1bj!K95 -> 0 | U48: x1 | V48: =m1bj!J119 -> 0.2 | W48: =m1bj!K119 -> 0.2
A49: x2 | B49: =m1bj!J3 -> 0 | C49: =m1bj!K3 -> 0 | E49: x2 | F49: =m1bj!J26 -> 0 | G49: =m1bj!K26 -> 0 | I49: x2 | J49: =m1bj!J49 -> 0 | K49: =m1bj!K49 -> 0 | M49: x2 | N49: =m1bj!J73 -> 0 | O49: =m1bj!K73 -> 0 | Q49: x2 | R49: =m1bj!J96 -> 0 | S49: =m1bj!K96 -> 0 | U49: x2 | V49: =m1bj!J120 -> 0 | W49: =m1bj!K120 -> 0
A50: x3 | B50: =m1bj!J4 -> 0 | C50: =m1bj!K4 -> 0 | E50: x3 | F50: =m1bj!J27 -> 0 | G50: =m1bj!K27 -> 0 | I50: x3 | J50: =m1bj!J50 -> 0 | K50: =m1bj!K50 -> 0 | M50: x3 | N50: =m1bj!J74 -> 0 | O50: =m1bj!K74 -> 0 | Q50: x3 | R50: =m1bj!J97 -> 0 | S50: =m1bj!K97 -> 0 | U50: x3 | V50: =m1bj!J121 -> 0 | W50: =m1bj!K121 -> 0
A51: x4 | B51: =m1bj!J5 -> 0 | C51: =m1bj!K5 -> 0 | E51: x4 | F51: =m1bj!J28 -> 0 | G51: =m1bj!K28 -> 0 | I51: x4 | J51: =m1bj!J51 -> 0 | K51: =m1bj!K51 -> 0 | M51: x4 | N51: =m1bj!J75 -> 0 | O51: =m1bj!K75 -> 0 | Q51: x4 | R51: =m1bj!J98 -> 0 | S51: =m1bj!K98 -> 0 | U51: x4 | V51: =m1bj!J122 -> 0 | W51: =m1bj!K122 -> 0
A52: x5 | B52: =m1bj!J6 -> 0 | C52: =m1bj!K6 -> 0 | E52: x5 | F52: =m1bj!J29 -> 0 | G52: =m1bj!K29 -> 0 | I52: x5 | J52: =m1bj!J52 -> 0 | K52: =m1bj!K52 -> 0 | M52: x5 | N52: =m1bj!J76 -> 0 | O52: =m1bj!K76 -> 0 | Q52: x5 | R52: =m1bj!J99 -> 0 | S52: =m1bj!K99 -> 0 | U52: x5 | V52: =m1bj!J123 -> 0 | W52: =m1bj!K123 -> 0
A53: x6 | B53: =m1bj!J7 -> 0.2 | C53: =m1bj!K7 -> 0.2 | E53: x6 | F53: =m1bj!J30 -> 0 | G53: =m1bj!K30 -> 0 | I53: x6 | J53: =m1bj!J53 -> 0 | K53: =m1bj!K53 -> 0 | M53: x6 | N53: =m1bj!J77 -> 0 | O53: =m1bj!K77 -> 0 | Q53: x6 | R53: =m1bj!J100 -> 0.4 | S53: =m1bj!K100 -> 0.4 | U53: x6 | V53: =m1bj!J124 -> 0 | W53: =m1bj!K124 -> 0
A54: x7 | B54: =m1bj!J8 -> 0 | C54: =m1bj!K8 -> 0 | E54: x7 | F54: =m1bj!J31 -> 0 | G54: =m1bj!K31 -> 0 | I54: x7 | J54: =m1bj!J54 -> 0 | K54: =m1bj!K54 -> 0 | M54: x7 | N54: =m1bj!J78 -> 0 | O54: =m1bj!K78 -> 0 | Q54: x7 | R54: =m1bj!J101 -> 0 | S54: =m1bj!K101 -> 0 | U54: x7 | V54: =m1bj!J125 -> 0 | W54: =m1bj!K125 -> 0
...

Sheet m1bj
A1: M1B1 | B1: miu | C1: v | E1: M1B2 | F1: miu | G1: v | I1: M1B3 | J1: miu | K1: v | M1: M1B4 | N1: miu | O1: v | Q1: M1B5 | R1: miu | S1: v | U1: M1B6 | V1: miu | W1: v
A2: x1 | B2: =ABS('rekap M'!C3-'rekap B'!C3) -> 0 | C2: =ABS('rekap M'!D3-'rekap B'!D3) -> 0 | E2: x1 | F2: =ABS('rekap M'!C3-'rekap B'!E3) -> 0 | G2: =ABS('rekap M'!D3-'rekap B'!F3) -> 0 | I2: x1 | J2: =ABS('rekap M'!C3-'rekap B'!G3) -> 0.2 | K2: =ABS('rekap M'!D3-'rekap B'!H3) -> 0.2 | M2: x1 | N2: =ABS('rekap M'!C3-'rekap B'!I3) -> 0.2 | O2: =ABS('rekap M'!D3-'rekap B'!J3) -> 0.2 | Q2: x1 | R2: =ABS('rekap M'!C3-'rekap B'!K3) -> 0.2 | S2: =ABS('rekap M'!D3-'rekap B'!L3) -> 0.2 | U2: x1 | V2: =ABS('rekap M'!C3-'rekap B'!M3) -> 0 | W2: =ABS('rekap M'!D3-'rekap B'!N3) -> 0
A3: x2 | B3: =ABS('rekap M'!C4-'rekap B'!C4) -> 0.4 | C3: =ABS('rekap M'!D4-'rekap B'!D4) -> 0.4 | E3: x2 | F3: =ABS('rekap M'!C4-'rekap B'!E4) -> 0.6 | G3: =ABS('rekap M'!D4-'rekap B'!F4) -> 0.6 | I3: x2 | J3: =ABS('rekap M'!C4-'rekap B'!G4) -> 0 | K3: =ABS('rekap M'!D4-'rekap B'!H4) -> 0 | M3: x2 | N3: =ABS('rekap M'!C4-'rekap B'!I4) -> 0 | O3: =ABS('rekap M'!D4-'rekap B'!J4) -> 0 | Q3: x2 | R3: =ABS('rekap M'!C4-'rekap B'!K4) -> 0.4 | S3: =ABS('rekap M'!D4-'rekap B'!L4) -> 0.4 | U3: x2 | V3: =ABS('rekap M'!C4-'rekap B'!M4) -> 0.6 | W3: =ABS('rekap M'!D4-'rekap B'!N4) -> 0.6
A4: x3 | B4: =ABS('rekap M'!C5-'rekap B'!C5) -> 0 | C4: =ABS('rekap M'!D5-'rekap B'!D5) -> 0 | E4: x3 | F4: =ABS('rekap M'!C5-'rekap B'!E5) -> 0 | G4: =ABS('rekap M'!D5-'rekap B'!F5) -> 0 | I4: x3 | J4: =ABS('rekap M'!C5-'rekap B'!G5) -> 0 | K4: =ABS('rekap M'!D5-'rekap B'!H5) -> 0 | M4: x3 | N4: =ABS('rekap M'!C5-'rekap B'!I5) -> 0 | O4: =ABS('rekap M'!D5-'rekap B'!J5) -> 0 | Q4: x3 | R4: =ABS('rekap M'!C5-'rekap B'!K5) -> 0 | S4: =ABS('rekap M'!D5-'rekap B'!L5) -> 0 | U4: x3 | V4: =ABS('rekap M'!C5-'rekap B'!M5) -> 0 | W4: =ABS('rekap M'!D5-'rekap B'!N5) -> 0
A5: x4 | B5: =ABS('rekap M'!C6-'rekap B'!C6) -> 0 | C5: =ABS('rekap M'!D6-'rekap B'!D6) -> 0 | E5: x4 | F5: =ABS('rekap M'!C6-'rekap B'!E6) -> 0 | G5: =ABS('rekap M'!D6-'rekap B'!F6) -> 0 | I5: x4 | J5: =ABS('rekap M'!C6-'rekap B'!G6) -> 0 | K5: =ABS('rekap M'!D6-'rekap B'!H6) -> 0 | M5: x4 | N5: =ABS('rekap M'!C6-'rekap B'!I6) -> 0 | O5: =ABS('rekap M'!D6-'rekap B'!J6) -> 0 | Q5: x4 | R5: =ABS('rekap M'!C6-'rekap B'!K6) -> 0 | S5: =ABS('rekap M'!D6-'rekap B'!L6) -> 0 | U5: x4 | V5: =ABS('rekap M'!C6-'rekap B'!M6) -> 0 | W5: =ABS('rekap M'!D6-'rekap B'!N6) -> 0
A6: x5 | B6: =ABS('rekap M'!C7-'rekap B'!C7) -> 0.2 | C6: =ABS('rekap M'!D7-'rekap B'!D7) -> 0.2 | E6: x5 | F6: =ABS('rekap M'!C7-'rekap B'!E7) -> 0 | G6: =ABS('rekap M'!D7-'rekap B'!F7) -> 0 | I6: x5 | J6: =ABS('rekap M'!C7-'rekap B'!G7) -> 0 | K6: =ABS('rekap M'!D7-'rekap B'!H7) -> 0 | M6: x5 | N6: =ABS('rekap M'!C7-'rekap B'!I7) -> 0 | O6: =ABS('rekap M'!D7-'rekap B'!J7) -> 0 | Q6: x5 | R6: =ABS('rekap M'!C7-'rekap B'!K7) -> 0 | S6: =ABS('rekap M'!D7-'rekap B'!L7) -> 0 | U6: x5 | V6: =ABS('rekap M'!C7-'rekap B'!M7) -> 0.2 | W6: =ABS('rekap M'!D7-'rekap B'!N7) -> 0.2
A7: x6 | B7: =ABS('rekap M'!C8-'rekap B'!C8) -> 0.2 | C7: =ABS('rekap M'!D8-'rekap B'!D8) -> 0.2 | E7: x6 | F7: =ABS('rekap M'!C8-'rekap B'!E8) -> 0.2 | G7: =ABS('rekap M'!D8-'rekap B'!F8) -> 0.2 | I7: x6 | J7: =ABS('rekap M'!C8-'rekap B'!G8) -> 0.2 | K7: =ABS('rekap M'!D8-'rekap B'!H8) -> 0.2 | M7: x6 | N7: =ABS('rekap M'!C8-'rekap B'!I8) -> 0.2 | O7: =ABS('rekap M'!D8-'rekap B'!J8) -> 0.2 | Q7: x6 | R7: =ABS('rekap M'!C8-'rekap B'!K8) -> 0 | S7: =ABS('rekap M'!D8-'rekap B'!L8) -> 0 | U7: x6 | V7: =ABS('rekap M'!C8-'rekap B'!M8) -> 0.2 | W7: =ABS('rekap M'!D8-'rekap B'!N8) -> 0.2
A8: x7 | B8: =ABS('rekap M'!C9-'rekap B'!C9) -> 0 | C8: =ABS('rekap M'!D9-'rekap B'!D9) -> 0 | E8: x7 | F8: =ABS('rekap M'!C9-'rekap B'!E9) -> 0 | G8: =ABS('rekap M'!D9-'rekap B'!F9) -> 0 | I8: x7 | J8: =ABS('rekap M'!C9-'rekap B'!G9) -> 0 | K8: =ABS('rekap M'!D9-'rekap B'!H9) -> 0 | M8: x7 | N8: =ABS('rekap M'!C9-'rekap B'!I9) -> 0 | O8: =ABS('rekap M'!D9-'rekap B'!J9) -> 0 | Q8: x7 | R8: =ABS('rekap M'!C9-'rekap B'!K9) -> 0 | S8: =ABS('rekap M'!D9-'rekap B'!L9) -> 0 | U8: x7 | V8: =ABS('rekap M'!C9-'rekap B'!M9) -> 0.4 | W8: =ABS('rekap M'!D9-'rekap B'!N9) -> 0.4
A9: x8 | B9: =ABS('rekap M'!C10-'rekap B'!C10) -> 0 | C9: =ABS('rekap M'!D10-'rekap B'!D10) -> 0 | E9: x8 | F9: =ABS('rekap M'!C10-'rekap B'!E10) -> 0.6 | G9: =ABS('rekap M'!D10-'rekap B'!F10) -> 0.6 | I9: x8 | J9: =ABS('rekap M'!C10-'rekap B'!G10) -> 0 | K9: =ABS('rekap M'!D10-'rekap B'!H10) -> 0 | M9: x8 | N9: =ABS('rekap M'!C10-'rekap B'!I10) -> 0 | O9: =ABS('rekap M'!D10-'rekap B'!J10) -> 0 | Q9: x8 | R9: =ABS('rekap M'!C10-'rekap B'!K10) -> 0.2 | S9: =ABS('rekap M'!D10-'rekap B'!L10) -> 0.2 | U9: x8 | V9: =ABS('rekap M'!C10-'rekap B'!M10) -> 0 | W9: =ABS('rekap M'!D10-'rekap B'!N10) -> 0
A10: x9 | B10: =ABS('rekap M'!C11-'rekap B'!C11) -> 0 | C10: =ABS('rekap M'!D11-'rekap B'!D11) -> 0 | E10: x9 | F10: =ABS('rekap M'!C11-'rekap B'!E11) -> 0.2 | G10: =ABS('rekap M'!D11-'rekap B'!F11) -> 0.2 | I10: x9 | J10: =ABS('rekap M'!C11-'rekap B'!G11) -> 0.2 | K10: =ABS('rekap M'!D11-'rekap B'!H11) -> 0.2 | M10: x9 | N10: =ABS('rekap M'!C11-'rekap B'!I11) -> 0.2 | O10: =ABS('rekap M'!D11-'rekap B'!J11) -> 0.2 | Q10: x9 | R10: =ABS('rekap M'!C11-'rekap B'!K11) -> 0 | S10: =ABS('rekap M'!D11-'rekap B'!L11) -> 0 | U10: x9 | V10: =ABS('rekap M'!C11-'rekap B'!M11) -> 0 | W10: =ABS('rekap M'!D11-'rekap B'!N11) -> 0
A11: x10 | B11: =ABS('rekap M'!C12-'rekap B'!C12) -> 0 | C11: =ABS('rekap M'!D12-'rekap B'!D12) -> 0 | E11: x10 | F11: =ABS('rekap M'!C12-'rekap B'!E12) -> 0 | G11: =ABS('rekap M'!D12-'rekap B'!F12) -> 0 | I11: x10 | J11: =ABS('rekap M'!C12-'rekap B'!G12) -> 0 | K11: =ABS('rekap M'!D12-'rekap B'!H12) -> 0 | M11: x10 | N11: =ABS('rekap M'!C12-'rekap B'!I12) -> 0 | O11: =ABS('rekap M'!D12-'rekap B'!J12) -> 0 | Q11: x10 | R11: =ABS('rekap M'!C12-'rekap B'!K12) -> 0 | S11: =ABS('rekap M'!D12-'rekap B'!L12) -> 0 | U11: x10 | V11: =ABS('rekap M'!C12-'rekap B'!M12) -> 0 | W11: =ABS('rekap M'!D12-'rekap B'!N12) -> 0
A12: x11 | B12: =ABS('rekap M'!C13-'rekap B'!C13) -> 0.2 | C12: =ABS('rekap M'!D13-'rekap B'!D13) -> 0.2 | E12: x11 | F12: =ABS('rekap M'!C13-'rekap B'!E13) -> 0.4 | G12: =ABS('rekap M'!D13-'rekap B'!F13) -> 0.4 | I12: x11 | J12: =ABS('rekap M'!C13-'rekap B'!G13) -> 0 | K12: =ABS('rekap M'!D13-'rekap B'!H13) -> 0 | M12: x11 | N12: =ABS('rekap M'!C13-'rekap B'!I13) -> 0 | O12: =ABS('rekap M'!D13-'rekap B'!J13) -> 0 | Q12: x11 | R12: =ABS('rekap M'!C13-'rekap B'!K13) -> 0.2 | S12: =ABS('rekap M'!D13-'rekap B'!L13) -> 0.2 | U12: x11 | V12: =ABS('rekap M'!C13-'rekap B'!M13) -> 0.2 | W12: =ABS('rekap M'!D13-'rekap B'!N13) -> 0.2
A13: x12 | B13: =ABS('rekap M'!C14-'rekap B'!C14) -> 0 | C13: =ABS('rekap M'!D14-'rekap B'!D14) -> 0 | E13: x12 | F13: =ABS('rekap M'!C14-'rekap B'!E14) -> 0 | G13: =ABS('rekap M'!D14-'rekap B'!F14) -> 0 | I13: x12 | J13: =ABS('rekap M'!C14-'rekap B'!G14) -> 0 | K13: =ABS('rekap M'!D14-'rekap B'!H14) -> 0 | M13: x12 | N13: =ABS('rekap M'!C14-'rekap B'!I14) -> 0 | O13: =ABS('rekap M'!D14-'rekap B'!J14) -> 0 | Q13: x12 | R13: =ABS('rekap M'!C14-'rekap B'!K14) -> 0 | S13: =ABS('rekap M'!D14-'rekap B'!L14) -> 0 | U13: x12 | V13: =ABS('rekap M'!C14-'rekap B'!M14) -> 0 | W13: =ABS('rekap M'!D14-'rekap B'!N14) -> 0
... A20: x19 | B20: =ABS('rekap M'!C21-'rekap B'!C21) -> 0.2 | C20: =ABS('rekap M'!D21-'rekap B'!D21) -> 0.2 | E20: x19 | F20: =ABS('rekap M'!C21-'rekap B'!E21) -> 0.2 | G20: =ABS('rekap M'!D21-'rekap B'!F21) -> 0.2 | I20: x19 | J20: =ABS('rekap M'!C21-'rekap B'!G21) -> 0.2 | K20: =ABS('rekap M'!D21-'rekap B'!H21) -> 0.2 | M20: x19 | N20: =ABS('rekap M'!C21-'rekap B'!I21) -> 0.2 | O20: =ABS('rekap M'!D21-'rekap B'!J21) -> 0.2 | Q20: x19 | R20: =ABS('rekap M'!C21-'rekap B'!K21) -> 0.2 | S20: =ABS('rekap M'!D21-'rekap B'!L21) -> 0.2 | U20: x19 | V20: =ABS('rekap M'!C21-'rekap B'!M21) -> 0.2 | W20: =ABS('rekap M'!D21-'rekap B'!N21) -> 0.2
A21: SUM | B21: =SUM(B2:B20) -> 2.4 | C21: =SUM(C2:C20) -> 2.4 | F21: =SUM(F2:F20) -> 3.2 | G21: =SUM(G2:G20) -> 3.2 | J21: =SUM(J2:J20) -> 1.8 | K21: =SUM(K2:K20) -> 1.8 | N21: =SUM(N2:N20) -> 2.4 | O21: =SUM(O2:O20) -> 2.4 | R21: =SUM(R2:R20) -> 2.4 | S21: =SUM(S2:S20) -> 2.4 | V21: =SUM(V2:V20) -> 2.6 | W21: =SUM(W2:W20) -> 2.6
A22: 1/19*SUM | D22: =1/19*(B21+C21) -> 0.25263158 | H22: =1/19*(F21+G21) -> 0.33684211 | L22: =1/19*(J21+K21) -> 0.18947368 | P22: =1/19*(N21+O21) -> 0.25263158 | T22: =1/19*(R21+S21) -> 0.25263158 | X22: =1/19*(V21+W21) -> 0.27368421 | Y22: min | Z22: =MIN(B22:Y22) -> 0.18947368
A24: M2B1 | B24: miu | C24: v | E24: M2B2 | F24: miu | G24: v | I24: M2B3 | J24: miu | K24: v | M24: M2B4 | N24: miu | O24: v | Q24: M2B5 | R24: miu | S24: v | U24: M2B6 | V24: miu | W24: v
A25: x1 | B25: =ABS('rekap M'!E3-'rekap B'!C3) -> 0 | C25: =ABS('rekap M'!F3-'rekap B'!D3) -> 0 | E25: x1 | F25: =ABS('rekap M'!E3-'rekap B'!E3) -> 0 | G25: =ABS('rekap M'!F3-'rekap B'!F3) -> 0 | I25: x1 | J25: =ABS('rekap M'!E3-'rekap B'!G3) -> 0.2 | K25: =ABS('rekap M'!F3-'rekap B'!H3) -> 0.2 | M25: x1 | N25: =ABS('rekap M'!E3-'rekap B'!I3) -> 0.2 | O25: =ABS('rekap M'!F3-'rekap B'!J3) -> 0.2 | Q25: x1 | R25: =ABS('rekap M'!E3-'rekap B'!K3) -> 0.2 | S25: =ABS('rekap M'!F3-'rekap B'!L3) -> 0.2 | U25: x1 | V25: =ABS('rekap M'!E3-'rekap B'!M3) -> 0 | W25: =ABS('rekap M'!F3-'rekap B'!N3) -> 0
A26: x2 | B26: =ABS('rekap M'!E4-'rekap B'!C4) -> 0.4 | C26: =ABS('rekap M'!F4-'rekap B'!D4) -> 0.4 | E26: x2 | F26: =ABS('rekap M'!E4-'rekap B'!E4) -> 0.6 | G26: =ABS('rekap M'!F4-'rekap B'!F4) -> 0.6 | I26: x2 | J26: =ABS('rekap M'!E4-'rekap B'!G4) -> 0 | K26: =ABS('rekap M'!F4-'rekap B'!H4) -> 0 | M26: x2 | N26: =ABS('rekap M'!E4-'rekap B'!I4) -> 0 | O26: =ABS('rekap M'!F4-'rekap B'!J4) -> 0 | Q26: x2 | R26: =ABS('rekap M'!E4-'rekap B'!K4) -> 0.4 | S26: =ABS('rekap M'!F4-'rekap B'!L4) -> 0.4 | U26: x2 | V26: =ABS('rekap M'!E4-'rekap B'!M4) -> 0.6 | W26: =ABS('rekap M'!F4-'rekap B'!N4) -> 0.6
A27: x3 | B27: =ABS('rekap M'!E5-'rekap B'!C5) -> 0 | C27: =ABS('rekap M'!F5-'rekap B'!D5) -> 0 | E27: x3 | F27: =ABS('rekap M'!E5-'rekap B'!E5) -> 0 | G27: =ABS('rekap M'!F5-'rekap B'!F5) -> 0 | I27: x3 | J27: =ABS('rekap M'!E5-'rekap B'!G5) -> 0 | K27: =ABS('rekap M'!F5-'rekap B'!H5) -> 0 | M27: x3 | N27: =ABS('rekap M'!E5-'rekap B'!I5) -> 0 | O27: =ABS('rekap M'!F5-'rekap B'!J5) -> 0 | Q27: x3 | R27: =ABS('rekap M'!E5-'rekap B'!K5) -> 0 | S27: =ABS('rekap M'!F5-'rekap B'!L5) -> 0 | U27: x3 | V27: =ABS('rekap M'!E5-'rekap B'!M5) -> 0 | W27: =ABS('rekap M'!F5-'rekap B'!N5) -> 0
A28: x4 | B28: =ABS('rekap M'!E6-'rekap B'!C6) -> 0 | C28: =ABS('rekap M'!F6-'rekap B'!D6) -> 0 | E28: x4 | F28: =ABS('rekap M'!E6-'rekap B'!E6) -> 0 | G28: =ABS('rekap M'!F6-'rekap B'!F6) -> 0 | I28: x4 | J28: =ABS('rekap M'!E6-'rekap B'!G6) -> 0 | K28: =ABS('rekap M'!F6-'rekap B'!H6) -> 0 | M28: x4 | N28: =ABS('rekap M'!E6-'rekap B'!I6) -> 0 | O28: =ABS('rekap M'!F6-'rekap B'!J6) -> 0 | Q28: x4 | R28: =ABS('rekap M'!E6-'rekap B'!K6) -> 0 | S28: =ABS('rekap M'!F6-'rekap B'!L6) -> 0 | U28: x4 | V28: =ABS('rekap M'!E6-'rekap B'!M6) -> 0 | W28: =ABS('rekap M'!F6-'rekap B'!N6) -> 0
A29: x5 | B29: =ABS('rekap M'!E7-'rekap B'!C7) -> 0.2 | C29: =ABS('rekap M'!F7-'rekap B'!D7) -> 0.2 | E29: x5 | F29: =ABS('rekap M'!E7-'rekap B'!E7) -> 0 | G29: =ABS('rekap M'!F7-'rekap B'!F7) -> 0 | I29: x5 | J29: =ABS('rekap M'!E7-'rekap B'!G7) -> 0 | K29: =ABS('rekap M'!F7-'rekap B'!H7) -> 0 | M29: x5 | N29: =ABS('rekap M'!E7-'rekap B'!I7) -> 0 | O29: =ABS('rekap M'!F7-'rekap B'!J7) -> 0 | Q29: x5 | R29: =ABS('rekap M'!E7-'rekap B'!K7) -> 0 | S29: =ABS('rekap M'!F7-'rekap B'!L7) -> 0 | U29: x5 | V29: =ABS('rekap M'!E7-'rekap B'!M7) -> 0.2 | W29: =ABS('rekap M'!F7-'rekap B'!N7) -> 0.2
A30: x6 | B30: =ABS('rekap M'!E8-'rekap B'!C8) -> 0.4 | C30: =ABS('rekap M'!F8-'rekap B'!D8) -> 0.4 | E30: x6 | F30: =ABS('rekap M'!E8-'rekap B'!E8) -> 0 | G30: =ABS('rekap M'!F8-'rekap B'!F8) -> 0 | I30: x6 | J30: =ABS('rekap M'!E8-'rekap B'!G8) -> 0 | K30: =ABS('rekap M'!F8-'rekap B'!H8) -> 0 | M30: x6 | N30: =ABS('rekap M'!E8-'rekap B'!I8) -> 0 | O30: =ABS('rekap M'!F8-'rekap B'!J8) -> 0 | Q30: x6 | R30: =ABS('rekap M'!E8-'rekap B'!K8) -> 0.2 | S30: =ABS('rekap M'!F8-'rekap B'!L8) -> 0.2 | U30: x6 | V30: =ABS('rekap M'!E8-'rekap B'!M8) -> 0 | W30: =ABS('rekap M'!F8-'rekap B'!N8) -> 0
A31: x7 | B31: =ABS('rekap M'!E9-'rekap B'!C9) -> 0 | C31: =ABS('rekap M'!F9-'rekap B'!D9) -> 0 | E31: x7 | F31: =ABS('rekap M'!E9-'rekap B'!E9) -> 0 | G31: =ABS('rekap M'!F9-'rekap B'!F9) -> 0 | I31: x7 | J31: =ABS('rekap M'!E9-'rekap B'!G9) -> 0 | K31: =ABS('rekap M'!F9-'rekap B'!H9) -> 0 | M31: x7 | N31: =ABS('rekap M'!E9-'rekap B'!I9) -> 0 | O31: =ABS('rekap M'!F9-'rekap B'!J9) -> 0 | Q31: x7 | R31: =ABS('rekap M'!E9-'rekap B'!K9) -> 0 | S31: =ABS('rekap M'!F9-'rekap B'!L9) -> 0 | U31: x7 | V31: =ABS('rekap M'!E9-'rekap B'!M9) -> 0.4 | W31: =ABS('rekap M'!F9-'rekap B'!N9) -> 0.4
A32: x8 | B32: =ABS('rekap M'!E10-'rekap B'!C10) -> 0 | C32: =ABS('rekap M'!F10-'rekap B'!D10) -> 0 | E32: x8 | F32: =ABS('rekap M'!E10-'rekap B'!E10) -> 0.6 | G32: =ABS('rekap M'!F10-'rekap B'!F10) -> 0.6 | I32: x8 | J32: =ABS('rekap M'!E10-'rekap B'!G10) -> 0 | K32: =ABS('rekap M'!F10-'rekap B'!H10) -> 0 | M32: x8 | N32: =ABS('rekap M'!E10-'rekap B'!I10) -> 0 | O32: =ABS('rekap M'!F10-'rekap B'!J10) -> 0 | Q32: x8 | R32: =ABS('rekap M'!E10-'rekap B'!K10) -> 0.2 | S32: =ABS('rekap M'!F10-'rekap B'!L10) -> 0.2 | U32: x8 | V32: =ABS('rekap M'!E10-'rekap B'!M10) -> 0 | W32: =ABS('rekap M'!F10-'rekap B'!N10) -> 0
A33: x9 | B33: =ABS('rekap M'!E11-'rekap B'!C11) -> 0.2 | C33: =ABS('rekap M'!F11-'rekap B'!D11) -> 0.2 | E33: x9 | F33: =ABS('rekap M'!E11-'rekap B'!E11) -> 0 | G33: =ABS('rekap M'!F11-'rekap B'!F11) -> 0 | I33: x9 | J33: =ABS('rekap M'!E11-'rekap B'!G11) -> 0.4 | K33: =ABS('rekap M'!F11-'rekap B'!H11) -> 0.4 | M33: x9 | N33: =ABS('rekap M'!E11-'rekap B'!I11) -> 0 | O33: =ABS('rekap M'!F11-'rekap B'!J11) -> 0 | Q33: x9 | R33: =ABS('rekap M'!E11-'rekap B'!K11) -> 0.2 | S33: =ABS('rekap M'!F11-'rekap B'!L11) -> 0.2 | U33: x9 | V33: =ABS('rekap M'!E11-'rekap B'!M11) -> 0.2 | W33: =ABS('rekap M'!F11-'rekap B'!N11) -> 0.2
A34: x10 | B34: =ABS('rekap M'!E12-'rekap B'!C12) -> 0 | C34: =ABS('rekap M'!F12-'rekap B'!D12) -> 0 | E34: x10 | F34: =ABS('rekap M'!E12-'rekap B'!E12) -> 0 | G34: =ABS('rekap M'!F12-'rekap B'!F12) -> 0 | I34: x10 | J34: =ABS('rekap M'!E12-'rekap B'!G12) -> 0 | K34: =ABS('rekap M'!F12-'rekap B'!H12) -> 0 | M34: x10 | N34: =ABS('rekap M'!E12-'rekap B'!I12) -> 0 | O34: =ABS('rekap M'!F12-'rekap B'!J12) -> 0 | Q34: x10 | R34: =ABS('rekap M'!E12-'rekap B'!K12) -> 0 | S34: =ABS('rekap M'!F12-'rekap B'!L12) -> 0 | U34: x10 | V34: =ABS('rekap M'!E12-'rekap B'!M12) -> 0 | W34: =ABS('rekap M'!F12-'rekap B'!N12) -> 0
A35: x11 | B35: =ABS('rekap M'!E13-'rekap B'!C13) -> 0.2 | C35: =ABS('rekap M'!F13-'rekap B'!D13) -> 0.2 | E35: x11 | F35: =ABS('rekap M'!E13-'rekap B'!E13) -> 0.4 | G35: =ABS('rekap M'!F13-'rekap B'!F13) -> 0.4 | I35: x11 | J35: =ABS('rekap M'!E13-'rekap B'!G13) -> 0 | K35: =ABS('rekap M'!F13-'rekap B'!H13) -> 0 | M35: x11 | N35: =ABS('rekap M'!E13-'rekap B'!I13) -> 0 | O35: =ABS('rekap M'!F13-'rekap B'!J13) -> 0 | Q35: x11 | R35: =ABS('rekap M'!E13-'rekap B'!K13) -> 0.2 | S35: =ABS('rekap M'!F13-'rekap B'!L13) -> 0.2 | U35: x11 | V35: =ABS('rekap M'!E13-'rekap B'!M13) -> 0.2 | W35: =ABS('rekap M'!F13-'rekap B'!N13) -> 0.2
A36: x12 | B36: =ABS('rekap M'!E14-'rekap B'!C14) -> 0 | C36: =ABS('rekap M'!F14-'rekap B'!D14) -> 0 | E36: x12 | F36: =ABS('rekap M'!E14-'rekap B'!E14) -> 0 | G36: =ABS('rekap M'!F14-'rekap B'!F14) -> 0 | I36: x12 | J36: =ABS('rekap M'!E14-'rekap B'!G14) -> 0 | K36: =ABS('rekap M'!F14-'rekap B'!H14) -> 0 | M36: x12 | N36: =ABS('rekap M'!E14-'rekap B'!I14) -> 0 | O36: =ABS('rekap M'!F14-'rekap B'!J14) -> 0 | Q36: x12 | R36: =ABS('rekap M'!E14-'rekap B'!K14) -> 0 | S36: =ABS('rekap M'!F14-'rekap B'!L14) -> 0 | U36: x12 | V36: =ABS('rekap M'!E14-'rekap B'!M14) -> 0 | W36: =ABS('rekap M'!F14-'rekap B'!N14) -> 0
... A43: x19 | B43: =ABS('rekap M'!E21-'rekap B'!C21) -> 0 | C43: =ABS('rekap M'!F21-'rekap B'!D21) -> 0 | E43: x19 | F43: =ABS('rekap M'!E21-'rekap B'!E21) -> 0 | G43: =ABS('rekap M'!F21-'rekap B'!F21) -> 0 | I43: x19 | J43: =ABS('rekap M'!E21-'rekap B'!G21) -> 0 | K43: =ABS('rekap M'!F21-'rekap B'!H21) -> 0 | M43: x19 | N43: =ABS('rekap M'!E21-'rekap B'!I21) -> 0 | O43: =ABS('rekap M'!F21-'rekap B'!J21) -> 0 | Q43: x19 | R43: =ABS('rekap M'!E21-'rekap B'!K21) -> 0 | S43: =ABS('rekap M'!F21-'rekap B'!L21) -> 0 | U43: x19 | V43: =ABS('rekap M'!E21-'rekap B'!M21) -> 0 | W43: =ABS('rekap M'!F21-'rekap B'!N21) -> 0
B44: =SUM(B25:B43) -> 1.8 | C44: =SUM(C25:C43) -> 1.8 | F44: =SUM(F25:F43) -> 2.2 | G44: =SUM(G25:G43) -> 2.2 | J44: =SUM(J25:J43) -> 1.6 | K44: =SUM(K25:K43) -> 1.6 | N44: =SUM(N25:N43) -> 1 | O44: =SUM(O25:O43) -> 1 | R44: =SUM(R25:R43) -> 1.8 | S44: =SUM(S25:S43) -> 1.8 | V44: =SUM(V25:V43) -> 3.2 | W44: =SUM(W25:W43) -> 3.2
A45: 1/19*SUM | D45: =1/19*(B44+C44) -> 0.18947368 | H45: =1/19*(F44+G44) -> 0.23157895 | L45: =1/19*(J44+K44) -> 0.16842105 | P45: =1/19*(N44+O44) -> 0.10526316 | T45: =1/19*(R44+S44) -> 0.18947368 | X45: =1/19*(V44+W44) -> 0.33684211 | Y45: min | Z45: =MIN(B45:Y45) -> 0.10526316
A47: M3B1 | B47: miu | C47: v | E47: M3B2 | F47: miu | G47: v | I47: M3B3 | J47: miu | K47: v | M47: M3B4 | N47: miu | O47: v | Q47: M3B5 | R47: miu | S47: v | U47: M3B6 | V47: miu | W47: v
A48: x1 | B48: =ABS('rekap M'!G3-'rekap B'!C3) -> 0 | C48: =ABS('rekap M'!H3-'rekap B'!D3) -> 0 | E48: x1 | F48: =ABS('rekap M'!G3-'rekap B'!E3) -> 0 | G48: =ABS('rekap M'!H3-'rekap B'!F3) -> 0 | I48: x1 | J48: =ABS('rekap M'!G3-'rekap B'!G3) -> 0.2 | K48: =ABS('rekap M'!H3-'rekap B'!H3) -> 0.2 | M48: x1 | N48: =ABS('rekap M'!G3-'rekap B'!I3) -> 0.2 | O48: =ABS('rekap M'!H3-'rekap B'!J3) -> 0.2 | Q48: x1 | R48: =ABS('rekap M'!G3-'rekap B'!K3) -> 0.2 | S48: =ABS('rekap M'!H3-'rekap B'!L3) -> 0.2 | U48: x1 | V48: =ABS('rekap M'!G3-'rekap B'!M3) -> 0 | W48: =ABS('rekap M'!H3-'rekap B'!N3) -> 0
A49: x2 | B49: =ABS('rekap M'!G4-'rekap B'!C4) -> 0.4 | C49: =ABS('rekap M'!H4-'rekap B'!D4) -> 0.4 | E49: x2 | F49: =ABS('rekap M'!G4-'rekap B'!E4) -> 0.6 | G49: =ABS('rekap M'!H4-'rekap B'!F4) -> 0.6 | I49: x2 | J49: =ABS('rekap M'!G4-'rekap B'!G4) -> 0 | K49: =ABS('rekap M'!H4-'rekap B'!H4) -> 0 | M49: x2 | N49: =ABS('rekap M'!G4-'rekap B'!I4) -> 0 | O49: =ABS('rekap M'!H4-'rekap B'!J4) -> 0 | Q49: x2 | R49: =ABS('rekap M'!G4-'rekap B'!K4) -> 0.4 | S49: =ABS('rekap M'!H4-'rekap B'!L4) -> 0.4 | U49: x2 | V49: =ABS('rekap M'!G4-'rekap B'!M4) -> 0.6 | W49: =ABS('rekap M'!H4-'rekap B'!N4) -> 0.6
A50: x3 | B50: =ABS('rekap M'!G5-'rekap B'!C5) -> 0 | C50: =ABS('rekap M'!H5-'rekap B'!D5) -> 0 | E50: x3 | F50: =ABS('rekap M'!G5-'rekap B'!E5) -> 0 | G50: =ABS('rekap M'!H5-'rekap B'!F5) -> 0 | I50: x3 | J50: =ABS('rekap M'!G5-'rekap B'!G5) -> 0 | K50: =ABS('rekap M'!H5-'rekap B'!H5) -> 0 | M50: x3 | N50: =ABS('rekap M'!G5-'rekap B'!I5) -> 0 | O50: =ABS('rekap M'!H5-'rekap B'!J5) -> 0 | Q50: x3 | R50: =ABS('rekap M'!G5-'rekap B'!K5) -> 0 | S50: =ABS('rekap M'!H5-'rekap B'!L5) -> 0 | U50: x3 | V50: =ABS('rekap M'!G5-'rekap B'!M5) -> 0 | W50: =ABS('rekap M'!H5-'rekap B'!N5) -> 0
A51: x4 | B51: =ABS('rekap M'!G6-'rekap B'!C6) -> 0 | C51: =ABS('rekap M'!H6-'rekap B'!D6) -> 0 | E51: x4 | F51: =ABS('rekap M'!G6-'rekap B'!E6) -> 0 | G51: =ABS('rekap M'!H6-'rekap B'!F6) -> 0 | I51: x4 | J51: =ABS('rekap M'!G6-'rekap B'!G6) -> 0 | K51: =ABS('rekap M'!H6-'rekap B'!H6) -> 0 | M51: x4 | N51: =ABS('rekap M'!G6-'rekap B'!I6) -> 0 | O51: =ABS('rekap M'!H6-'rekap B'!J6) -> 0 | Q51: x4 | R51: =ABS('rekap M'!G6-'rekap B'!K6) -> 0 | S51: =ABS('rekap M'!H6-'rekap B'!L6) -> 0 | U51: x4 | V51: =ABS('rekap M'!G6-'rekap B'!M6) -> 0 | W51: =ABS('rekap M'!H6-'rekap B'!N6) -> 0
A52: x5 | B52: =ABS('rekap M'!G7-'rekap B'!C7) -> 0.2 | C52: =ABS('rekap M'!H7-'rekap B'!D7) -> 0.2 | E52: x5 | F52: =ABS('rekap M'!G7-'rekap B'!E7) -> 0 | G52: =ABS('rekap M'!H7-'rekap B'!F7) -> 0 | I52: x5 | J52: =ABS('rekap M'!G7-'rekap B'!G7) -> 0 | K52: =ABS('rekap M'!H7-'rekap B'!H7) -> 0 | M52: x5 | N52: =ABS('rekap M'!G7-'rekap B'!I7) -> 0 | O52: =ABS('rekap M'!H7-'rekap B'!J7) -> 0 | Q52: x5 | R52: =ABS('rekap M'!G7-'rekap B'!K7) -> 0 | S52: =ABS('rekap M'!H7-'rekap B'!L7) -> 0 | U52: x5 | V52: =ABS('rekap M'!G7-'rekap B'!M7) -> 0.2 | W52: =ABS('rekap M'!H7-'rekap B'!N7) -> 0.2
A53: x6 | B53: =ABS('rekap M'!G8-'rekap B'!C8) -> 0.4 | C53: =ABS('rekap M'!H8-'rekap B'!D8) -> 0.4 | E53: x6 | F53: =ABS('rekap M'!G8-'rekap B'!E8) -> 0 | G53: =ABS('rekap M'!H8-'rekap B'!F8) -> 0 | I53: x6 | J53: =ABS('rekap M'!G8-'rekap B'!G8) -> 0 | K53: =ABS('rekap M'!H8-'rekap B'!H8) -> 0 | M53: x6 | N53: =ABS('rekap M'!G8-'rekap B'!I8) -> 0 | O53: =ABS('rekap M'!H8-'rekap B'!J8) -> 0 | Q53: x6 | R53: =ABS('rekap M'!G8-'rekap B'!K8) -> 0.2 | S53: =ABS('rekap M'!H8-'rekap B'!L8) -> 0.2 | U53: x6 | V53: =ABS('rekap M'!G8-'rekap B'!M8) -> 0 | W53: =ABS('rekap M'!H8-'rekap B'!N8) -> 0
A54: x7 | B54: =ABS('rekap M'!G9-'rekap B'!C9) -> 0 | C54: =ABS('rekap M'!H9-'rekap B'!D9) -> 0 | E54: x7 | F54: =ABS('rekap M'!G9-'rekap B'!E9) -> 0 | G54: =ABS('rekap M'!H9-'rekap B'!F9) -> 0 | I54: x7 | J54: =ABS('rekap M'!G9-'rekap B'!G9) -> 0 | K54: =ABS('rekap M'!H9-'rekap B'!H9) -> 0 | M54: x7 | N54: =ABS('rekap M'!G9-'rekap B'!I9) -> 0 | O54: =ABS('rekap M'!H9-'rekap B'!J9) -> 0 | Q54: x7 | R54: =ABS('rekap M'!G9-'rekap B'!K9) -> 0 | S54: =ABS('rekap M'!H9-'rekap B'!L9) -> 0 | U54: x7 | V54: =ABS('rekap M'!G9-'rekap B'!M9) -> 0.4 | W54: =ABS('rekap M'!H9-'rekap B'!N9) -> 0.4
...

Sheet rekap MG
A1: ASPEK | B1: KRITERIA | C1: MG1 | E1: MG2 | G1: MG3 | I1: MG4 | K1: MG5 | M1: MG6
C2: miu | D2: v | E2: miu | F2: v | G2: miu | H2: v | I2: miu | J2: v | K2: miu | L2: v | M2: miu | N2: v
A3: 1. KONDISI BANGUNAN GEDUNG | B3: a. Ketidakteraturan Bangunan | C3: =IF(rekap!O2=5,0.8,IF(rekap!O2=3,0.6,IF(rekap!O2=1,0.4,0.2))) -> 0.2 | D3: =IF(rekap!O2=5,0.1,IF(rekap!O2=3,0.3,IF(rekap!O2=1,0.5,0.7))) -> 0.7 | E3: =IF(rekap!P2=5,0.8,IF(rekap!P2=3,0.6,IF(rekap!P2=1,0.4,0.2))) -> 0.4 | F3: =IF(rekap!P2=5,0.1,IF(rekap!P2=3,0.3,IF(rekap!P2=1,0.5,0.7))) -> 0.5 | G3: =IF(rekap!Q2=5,0.8,IF(rekap!Q2=3,0.6,IF(rekap!Q2=1,0.4,0.2))) -> 0.2 | H3: =IF(rekap!Q2=5,0.1,IF(rekap!Q2=3,0.3,IF(rekap!Q2=1,0.5,0.7))) -> 0.7 | I3: =IF(rekap!R2=5,0.8,IF(rekap!R2=3,0.6,IF(rekap!R2=1,0.4,0.2))) -> 0.2 | J3: =IF(rekap!R2=5,0.1,IF(rekap!R2=3,0.3,IF(rekap!R2=1,0.5,0.7))) -> 0.7 | K3: =IF(rekap!S2=5,0.8,IF(rekap!S2=3,0.6,IF(rekap!S2=1,0.4,0.2))) -> 0.2 | L3: =IF(rekap!S2=5,0.1,IF(rekap!S2=3,0.3,IF(rekap!S2=1,0.5,0.7))) -> 0.7 | M3: =IF(rekap!T2=5,0.8,IF(rekap!T2=3,0.6,IF(rekap!T2=1,0.4,0.2))) -> 0.4 | N3: =IF(rekap!T2=5,0.1,IF(rekap!T2=3,0.3,IF(rekap!T2=1,0.5,0.7))) -> 0.5
B4: b. Kepadatan Bangunan | C4: =IF(rekap!O3=5,0.8,IF(rekap!O3=3,0.6,IF(rekap!O3=1,0.4,0.2))) -> 0.2 | D4: =IF(rekap!O3=5,0.1,IF(rekap!O3=3,0.3,IF(rekap!O3=1,0.5,0.7))) -> 0.7 | E4: =IF(rekap!P3=5,0.8,IF(rekap!P3=3,0.6,IF(rekap!P3=1,0.4,0.2))) -> 0.8 | F4: =IF(rekap!P3=5,0.1,IF(rekap!P3=3,0.3,IF(rekap!P3=1,0.5,0.7))) -> 0.1 | G4: =IF(rekap!Q3=5,0.8,IF(rekap!Q3=3,0.6,IF(rekap!Q3=1,0.4,0.2))) -> 0.2 | H4: =IF(rekap!Q3=5,0.1,IF(rekap!Q3=3,0.3,IF(rekap!Q3=1,0.5,0.7))) -> 0.7 | I4: =IF(rekap!R3=5,0.8,IF(rekap!R3=3,0.6,IF(rekap!R3=1,0.4,0.2))) -> 0.2 | J4: =IF(rekap!R3=5,0.1,IF(rekap!R3=3,0.3,IF(rekap!R3=1,0.5,0.7))) -> 0.7 | K4: =IF(rekap!S3=5,0.8,IF(rekap!S3=3,0.6,IF(rekap!S3=1,0.4,0.2))) -> 0.6 | L4: =IF(rekap!S3=5,0.1,IF(rekap!S3=3,0.3,IF(rekap!S3=1,0.5,0.7))) -> 0.3 | M4: =IF(rekap!T3=5,0.8,IF(rekap!T3=3,0.6,IF(rekap!T3=1,0.4,0.2))) -> 0.8 | N4: =IF(rekap!T3=5,0.1,IF(rekap!T3=3,0.3,IF(rekap!T3=1,0.5,0.7))) -> 0.1
B5: c. Ketidaksesuaian dengan Persy Teknis Bangunan | C5: =IF(rekap!O4=5,0.8,IF(rekap!O4=3,0.6,IF(rekap!O4=1,0.4,0.2))) -> 0.2 | D5: =IF(rekap!O4=5,0.1,IF(rekap!O4=3,0.3,IF(rekap!O4=1,0.5,0.7))) -> 0.7 | E5: =IF(rekap!P4=5,0.8,IF(rekap!P4=3,0.6,IF(rekap!P4=1,0.4,0.2))) -> 0.2 | F5: =IF(rekap!P4=5,0.1,IF(rekap!P4=3,0.3,IF(rekap!P4=1,0.5,0.7))) -> 0.7 | G5: =IF(rekap!Q4=5,0.8,IF(rekap!Q4=3,0.6,IF(rekap!Q4=1,0.4,0.2))) -> 0.2 | H5: =IF(rekap!Q4=5,0.1,IF(rekap!Q4=3,0.3,IF(rekap!Q4=1,0.5,0.7))) -> 0.7 | I5: =IF(rekap!R4=5,0.8,IF(rekap!R4=3,0.6,IF(rekap!R4=1,0.4,0.2))) -> 0.2 | J5: =IF(rekap!R4=5,0.1,IF(rekap!R4=3,0.3,IF(rekap!R4=1,0.5,0.7))) -> 0.7 | K5: =IF(rekap!S4=5,0.8,IF(rekap!S4=3,0.6,IF(rekap!S4=1,0.4,0.2))) -> 0.2 | L5: =IF(rekap!S4=5,0.1,IF(rekap!S4=3,0.3,IF(rekap!S4=1,0.5,0.7))) -> 0.7 | M5: =IF(rekap!T4=5,0.8,IF(rekap!T4=3,0.6,IF(rekap!T4=1,0.4,0.2))) -> 0.2 | N5: =IF(rekap!T4=5,0.1,IF(rekap!T4=3,0.3,IF(rekap!T4=1,0.5,0.7))) -> 0.7
A6: 2. Kondisi Jalan Lingkungan | B6: a. Cakupan Pelayanan Jalan Lingkungan | C6: =IF(rekap!O5=5,0.8,IF(rekap!O5=3,0.6,IF(rekap!O5=1,0.4,0.2))) -> 0.2 | D6: =IF(rekap!O5=5,0.1,IF(rekap!O5=3,0.3,IF(rekap!O5=1,0.5,0.7))) -> 0.7 | E6: =IF(rekap!P5=5,0.8,IF(rekap!P5=3,0.6,IF(rekap!P5=1,0.4,0.2))) -> 0.2 | F6: =IF(rekap!P5=5,0.1,IF(rekap!P5=3,0.3,IF(rekap!P5=1,0.5,0.7))) -> 0.7 | G6: =IF(rekap!Q5=5,0.8,IF(rekap!Q5=3,0.6,IF(rekap!Q5=1,0.4,0.2))) -> 0.2 | H6: =IF(rekap!Q5=5,0.1,IF(rekap!Q5=3,0.3,IF(rekap!Q5=1,0.5,0.7))) -> 0.7 | I6: =IF(rekap!R5=5,0.8,IF(rekap!R5=3,0.6,IF(rekap!R5=1,0.4,0.2))) -> 0.2 | J6: =IF(rekap!R5=5,0.1,IF(rekap!R5=3,0.3,IF(rekap!R5=1,0.5,0.7))) -> 0.7 | K6: =IF(rekap!S5=5,0.8,IF(rekap!S5=3,0.6,IF(rekap!S5=1,0.4,0.2))) -> 0.2 | L6: =IF(rekap!S5=5,0.1,IF(rekap!S5=3,0.3,IF(rekap!S5=1,0.5,0.7))) -> 0.7 | M6: =IF(rekap!T5=5,0.8,IF(rekap!T5=3,0.6,IF(rekap!T5=1,0.4,0.2))) -> 0.2 | N6: =IF(rekap!T5=5,0.1,IF(rekap!T5=3,0.3,IF(rekap!T5=1,0.5,0.7))) -> 0.7
B7: b. Kualitas Permukaan Jalan lingkungan | C7: =IF(rekap!O6=5,0.8,IF(rekap!O6=3,0.6,IF(rekap!O6=1,0.4,0.2))) -> 0.2 | D7: =IF(rekap!O6=5,0.1,IF(rekap!O6=3,0.3,IF(rekap!O6=1,0.5,0.7))) -> 0.7 | E7: =IF(rekap!P6=5,0.8,IF(rekap!P6=3,0.6,IF(rekap!P6=1,0.4,0.2))) -> 0.2 | F7: =IF(rekap!P6=5,0.1,IF(rekap!P6=3,0.3,IF(rekap!P6=1,0.5,0.7))) -> 0.7 | G7: =IF(rekap!Q6=5,0.8,IF(rekap!Q6=3,0.6,IF(rekap!Q6=1,0.4,0.2))) -> 0.2 | H7: =IF(rekap!Q6=5,0.1,IF(rekap!Q6=3,0.3,IF(rekap!Q6=1,0.5,0.7))) -> 0.7 | I7: =IF(rekap!R6=5,0.8,IF(rekap!R6=3,0.6,IF(rekap!R6=1,0.4,0.2))) -> 0.2 | J7: =IF(rekap!R6=5,0.1,IF(rekap!R6=3,0.3,IF(rekap!R6=1,0.5,0.7))) -> 0.7 | K7: =IF(rekap!S6=5,0.8,IF(rekap!S6=3,0.6,IF(rekap!S6=1,0.4,0.2))) -> 0.2 | L7: =IF(rekap!S6=5,0.1,IF(rekap!S6=3,0.3,IF(rekap!S6=1,0.5,0.7))) -> 0.7 | M7: =IF(rekap!T6=5,0.8,IF(rekap!T6=3,0.6,IF(rekap!T6=1,0.4,0.2))) -> 0.4 | N7: =IF(rekap!T6=5,0.1,IF(rekap!T6=3,0.3,IF(rekap!T6=1,0.5,0.7))) -> 0.5
A8: 3. Kondisi Penyediaan Air Minum | B8: a. Ketersediaan Akses Aman Air Minum | C8: =IF(rekap!O7=5,0.8,IF(rekap!O7=3,0.6,IF(rekap!O7=1,0.4,0.2))) -> 0.2 | D8: =IF(rekap!O7=5,0.1,IF(rekap!O7=3,0.3,IF(rekap!O7=1,0.5,0.7))) -> 0.7 | E8: =IF(rekap!P7=5,0.8,IF(rekap!P7=3,0.6,IF(rekap!P7=1,0.4,0.2))) -> 0.2 | F8: =IF(rekap!P7=5,0.1,IF(rekap!P7=3,0.3,IF(rekap!P7=1,0.5,0.7))) -> 0.7 | G8: =IF(rekap!Q7=5,0.8,IF(rekap!Q7=3,0.6,IF(rekap!Q7=1,0.4,0.2))) -> 0.2 | H8: =IF(rekap!Q7=5,0.1,IF(rekap!Q7=3,0.3,IF(rekap!Q7=1,0.5,0.7))) -> 0.7 | I8: =IF(rekap!R7=5,0.8,IF(rekap!R7=3,0.6,IF(rekap!R7=1,0.4,0.2))) -> 0.2 | J8: =IF(rekap!R7=5,0.1,IF(rekap!R7=3,0.3,IF(rekap!R7=1,0.5,0.7))) -> 0.7 | K8: =IF(rekap!S7=5,0.8,IF(rekap!S7=3,0.6,IF(rekap!S7=1,0.4,0.2))) -> 0.4 | L8: =IF(rekap!S7=5,0.1,IF(rekap!S7=3,0.3,IF(rekap!S7=1,0.5,0.7))) -> 0.5 | M8: =IF(rekap!T7=5,0.8,IF(rekap!T7=3,0.6,IF(rekap!T7=1,0.4,0.2))) -> 0.2 | N8: =IF(rekap!T7=5,0.1,IF(rekap!T7=3,0.3,IF(rekap!T7=1,0.5,0.7))) -> 0.7
B9: b. Tidak terpenuhinya Kebutuhan Air Minum | C9: =IF(rekap!O8=5,0.8,IF(rekap!O8=3,0.6,IF(rekap!O8=1,0.4,0.2))) -> 0.2 | D9: =IF(rekap!O8=5,0.1,IF(rekap!O8=3,0.3,IF(rekap!O8=1,0.5,0.7))) -> 0.7 | E9: =IF(rekap!P8=5,0.8,IF(rekap!P8=3,0.6,IF(rekap!P8=1,0.4,0.2))) -> 0.2 | F9: =IF(rekap!P8=5,0.1,IF(rekap!P8=3,0.3,IF(rekap!P8=1,0.5,0.7))) -> 0.7 | G9: =IF(rekap!Q8=5,0.8,IF(rekap!Q8=3,0.6,IF(rekap!Q8=1,0.4,0.2))) -> 0.2 | H9: =IF(rekap!Q8=5,0.1,IF(rekap!Q8=3,0.3,IF(rekap!Q8=1,0.5,0.7))) -> 0.7 | I9: =IF(rekap!R8=5,0.8,IF(rekap!R8=3,0.6,IF(rekap!R8=1,0.4,0.2))) -> 0.2 | J9: =IF(rekap!R8=5,0.1,IF(rekap!R8=3,0.3,IF(rekap!R8=1,0.5,0.7))) -> 0.7 | K9: =IF(rekap!S8=5,0.8,IF(rekap!S8=3,0.6,IF(rekap!S8=1,0.4,0.2))) -> 0.2 | L9: =IF(rekap!S8=5,0.1,IF(rekap!S8=3,0.3,IF(rekap!S8=1,0.5,0.7))) -> 0.7 | M9: =IF(rekap!T8=5,0.8,IF(rekap!T8=3,0.6,IF(rekap!T8=1,0.4,0.2))) -> 0.6 | N9: =IF(rekap!T8=5,0.1,IF(rekap!T8=3,0.3,IF(rekap!T8=1,0.5,0.7))) -> 0.3
A10: 4. Kondisi Drainase Lingkungan | B10: a. Ketidakmampuan Mengalirkan Limpasan Air | C10: =IF(rekap!O9=5,0.8,IF(rekap!O9=3,0.6,IF(rekap!O9=1,0.4,0.2))) -> 0.2 | D10: =IF(rekap!O9=5,0.1,IF(rekap!O9=3,0.3,IF(rekap!O9=1,0.5,0.7))) -> 0.7 | E10: =IF(rekap!P9=5,0.8,IF(rekap!P9=3,0.6,IF(rekap!P9=1,0.4,0.2))) -> 0.8 | F10: =IF(rekap!P9=5,0.1,IF(rekap!P9=3,0.3,IF(rekap!P9=1,0.5,0.7))) -> 0.1 | G10: =IF(rekap!Q9=5,0.8,IF(rekap!Q9=3,0.6,IF(rekap!Q9=1,0.4,0.2))) -> 0.2 | H10: =IF(rekap!Q9=5,0.1,IF(rekap!Q9=3,0.3,IF(rekap!Q9=1,0.5,0.7))) -> 0.7 | I10: =IF(rekap!R9=5,0.8,IF(rekap!R9=3,0.6,IF(rekap!R9=1,0.4,0.2))) -> 0.2 | J10: =IF(rekap!R9=5,0.1,IF(rekap!R9=3,0.3,IF(rekap!R9=1,0.5,0.7))) -> 0.7 | K10: =IF(rekap!S9=5,0.8,IF(rekap!S9=3,0.6,IF(rekap!S9=1,0.4,0.2))) -> 0.4 | L10: =IF(rekap!S9=5,0.1,IF(rekap!S9=3,0.3,IF(rekap!S9=1,0.5,0.7))) -> 0.5 | M10: =IF(rekap!T9=5,0.8,IF(rekap!T9=3,0.6,IF(rekap!T9=1,0.4,0.2))) -> 0.2 | N10: =IF(rekap!T9=5,0.1,IF(rekap!T9=3,0.3,IF(rekap!T9=1,0.5,0.7))) -> 0.7
B11: b. Ketidaktersediaan Drainase | C11: =IF(rekap!O10=5,0.8,IF(rekap!O10=3,0.6,IF(rekap!O10=1,0.4,0.2))) -> 0.2 | D11: =IF(rekap!O10=5,0.1,IF(rekap!O10=3,0.3,IF(rekap!O10=1,0.5,0.7))) -> 0.7 | E11: =IF(rekap!P10=5,0.8,IF(rekap!P10=3,0.6,IF(rekap!P10=1,0.4,0.2))) -> 0.2 | F11: =IF(rekap!P10=5,0.1,IF(rekap!P10=3,0.3,IF(rekap!P10=1,0.5,0.7))) -> 0.7 | G11: =IF(rekap!Q10=5,0.8,IF(rekap!Q10=3,0.6,IF(rekap!Q10=1,0.4,0.2))) -> 0.6 | H11: =IF(rekap!Q10=5,0.1,IF(rekap!Q10=3,0.3,IF(rekap!Q10=1,0.5,0.7))) -> 0.3 | I11: =IF(rekap!R10=5,0.8,IF(rekap!R10=3,0.6,IF(rekap!R10=1,0.4,0.2))) -> 0.2 | J11: =IF(rekap!R10=5,0.1,IF(rekap!R10=3,0.3,IF(rekap!R10=1,0.5,0.7))) -> 0.7 | K11: =IF(rekap!S10=5,0.8,IF(rekap!S10=3,0.6,IF(rekap!S10=1,0.4,0.2))) -> 0.4 | L11: =IF(rekap!S10=5,0.1,IF(rekap!S10=3,0.3,IF(rekap!S10=1,0.5,0.7))) -> 0.5 | M11: =IF(rekap!T10=5,0.8,IF(rekap!T10=3,0.6,IF(rekap!T10=1,0.4,0.2))) -> 0.4 | N11: =IF(rekap!T10=5,0.1,IF(rekap!T10=3,0.3,IF(rekap!T10=1,0.5,0.7))) -> 0.5
B12: c. Ketidakterhubungan dgn Sistem Drainase Kota | C12: =IF(rekap!O11=5,0.8,IF(rekap!O11=3,0.6,IF(rekap!O11=1,0.4,0.2))) -> 0.2 | D12: =IF(rekap!O11=5,0.1,IF(rekap!O11=3,0.3,IF(rekap!O11=1,0.5,0.7))) -> 0.7 | E12: =IF(rekap!P11=5,0.8,IF(rekap!P11=3,0.6,IF(rekap!P11=1,0.4,0.2))) -> 0.2 | F12: =IF(rekap!P11=5,0.1,IF(rekap!P11=3,0.3,IF(rekap!P11=1,0.5,0.7))) -> 0.7 | G12: =IF(rekap!Q11=5,0.8,IF(rekap!Q11=3,0.6,IF(rekap!Q11=1,0.4,0.2))) -> 0.2 | H12: =IF(rekap!Q11=5,0.1,IF(rekap!Q11=3,0.3,IF(rekap!Q11=1,0.5,0.7))) -> 0.7 | I12: =IF(rekap!R11=5,0.8,IF(rekap!R11=3,0.6,IF(rekap!R11=1,0.4,0.2))) -> 0.2 | J12: =IF(rekap!R11=5,0.1,IF(rekap!R11=3,0.3,IF(rekap!R11=1,0.5,0.7))) -> 0.7 | K12: =IF(rekap!S11=5,0.8,IF(rekap!S11=3,0.6,IF(rekap!S11=1,0.4,0.2))) -> 0.2 | L12: =IF(rekap!S11=5,0.1,IF(rekap!S11=3,0.3,IF(rekap!S11=1,0.5,0.7))) -> 0.7 | M12: =IF(rekap!T11=5,0.8,IF(rekap!T11=3,0.6,IF(rekap!T11=1,0.4,0.2))) -> 0.2 | N12: =IF(rekap!T11=5,0.1,IF(rekap!T11=3,0.3,IF(rekap!T11=1,0.5,0.7))) -> 0.7
